<sdf version='1.5'>
  <world name='default'>
    <light name='sun' type='directional'>
      <cast_shadows>1</cast_shadows>
      <pose frame=''>0 0 10 0 -0 0</pose>
      <diffuse>0.8 0.8 0.8 1</diffuse>
      <specular>0.2 0.2 0.2 1</specular>
      <attenuation>
        <range>1000</range>
        <constant>0.9</constant>
        <linear>0.01</linear>
        <quadratic>0.001</quadratic>
      </attenuation>
      <direction>-0.5 0.1 -0.9</direction>
    </light>
    <model name='ground_plane'>
      <static>1</static>
      <link name='link'>
        <collision name='collision'>
          <geometry>
            <plane>
              <normal>0 0 1</normal>
              <size>100 100</size>
            </plane>
          </geometry>
          <surface>
            <friction>
              <ode>
                <mu>100</mu>
                <mu2>50</mu2>
              </ode>
            </friction>
            <contact>
              <ode/>
            </contact>
            <bounce/>
          </surface>
          <max_contacts>10</max_contacts>
        </collision>
        <visual name='visual'>
          <cast_shadows>0</cast_shadows>
          <geometry>
            <plane>
              <normal>0 0 1</normal>
              <size>100 100</size>
            </plane>
          </geometry>
          <material>
            <script>
              <uri>file://media/materials/scripts/gazebo.material</uri>
              <name>Gazebo/Grey</name>
            </script>
          </material>
        </visual>
        <self_collide>0</self_collide>
        <kinematic>0</kinematic>
        <gravity>1</gravity>
      </link>
    </model>
    <physics name='default_physics' default='0' type='ode'>
      <max_step_size>0.001</max_step_size>
      <real_time_factor>1</real_time_factor>
      <real_time_update_rate>1000</real_time_update_rate>
      <gravity>0 0 -9.8</gravity>
      <magnetic_field>6e-06 2.3e-05 -4.2e-05</magnetic_field>
    </physics>
    <scene>
      <ambient>0.4 0.4 0.4 1</ambient>
      <background>0.7 0.7 0.7 1</background>
      <shadows>1</shadows>
    </scene>
    <spherical_coordinates>
      <surface_model>EARTH_WGS84</surface_model>
      <latitude_deg>0</latitude_deg>
      <longitude_deg>0</longitude_deg>
      <elevation>0</elevation>
      <heading_deg>0</heading_deg>
    </spherical_coordinates>
    <model name='HoLLiE'>
      <pose frame=''>1 -1 0.5 0 -0 0</pose>
      <link name='base_link'>
        <pose frame=''>0 0 0 0 -0 0</pose>
        <inertial>
          <pose frame=''>0 0 0 0 -0 0</pose>
          <mass>1000</mass>
          <inertia>
            <ixx>100</ixx>
            <ixy>0</ixy>
            <ixz>0</ixz>
            <iyy>100</iyy>
            <iyz>0</iyz>
            <izz>100</izz>
          </inertia>
        </inertial>
        <collision name='base_link_collision'>
          <pose frame=''>0 0 0.5 0 -0 0</pose>
          <geometry>
            <mesh>
              <scale>1 1 1</scale>
              <uri>model://arm_robot/collisions/COL_COL_COL_VIS_VIS_VIS_VIS_VIS_VIS_VIS_Table_0_0_0_0_0_0_0.000.dae</uri>
            </mesh>
          </geometry>
          <max_contacts>10</max_contacts>
          <surface>
            <contact>
              <ode/>
            </contact>
            <bounce/>
            <friction>
              <ode/>
            </friction>
          </surface>
        </collision>
        <collision name='base_link_collision_base_link_1'>
          <pose frame=''>0 0 0.5 0 -0 0</pose>
          <geometry>
            <mesh>
              <scale>1 1 1</scale>
              <uri>model://arm_robot/collisions/COL_COL_COL_VIS_VIS_VIS_VIS_VIS_VIS_VIS_Table_0_0_0_0_0_0_0.001.dae</uri>
            </mesh>
          </geometry>
          <max_contacts>10</max_contacts>
          <surface>
            <contact>
              <ode/>
            </contact>
            <bounce/>
            <friction>
              <ode/>
            </friction>
          </surface>
        </collision>
        <collision name='base_link_collision_base_link_2'>
          <pose frame=''>0 0 0.5 0 -0 0</pose>
          <geometry>
            <mesh>
              <scale>1 1 1</scale>
              <uri>model://arm_robot/collisions/COL_COL_COL_VIS_VIS_VIS_VIS_VIS_VIS_VIS_Table_0_0_0_0_0_0_0_0_0.dae</uri>
            </mesh>
          </geometry>
          <max_contacts>10</max_contacts>
          <surface>
            <contact>
              <ode/>
            </contact>
            <bounce/>
            <friction>
              <ode/>
            </friction>
          </surface>
        </collision>
        <visual name='base_link_visual'>
          <pose frame=''>0 0 0.5 0 -0 0</pose>
          <geometry>
            <mesh>
              <scale>1 1 1</scale>
              <uri>model://arm_robot/meshes/VIS_COL_COL_VIS_VIS_VIS_VIS_VIS_VIS_VIS_Table_0_0_0_0_0_0_0_0_0.dae</uri>
            </mesh>
          </geometry>
        </visual>
        <self_collide>0</self_collide>
        <kinematic>0</kinematic>
        <gravity>1</gravity>
      </link>
      <link name='hollie_real_left_arm_0_joint_link'>
        <pose frame=''>0 -0.4 1 0 -0 1.62316</pose>
        <inertial>
          <pose frame=''>0 0 0 0 -0 0</pose>
          <mass>0.29364</mass>
          <inertia>
            <ixx>0.01</ixx>
            <ixy>0</ixy>
            <ixz>0</ixz>
            <iyy>0.01</iyy>
            <iyz>0</iyz>
            <izz>0.01</izz>
          </inertia>
        </inertial>
        <self_collide>0</self_collide>
        <kinematic>0</kinematic>
        <gravity>1</gravity>
      </link>
      <joint name='hollie_real_left_arm_0_joint' type='prismatic'>
        <child>hollie_real_left_arm_0_joint_link</child>
        <parent>base_link</parent>
        <axis>
          <xyz>-0.052336 0.99863 0</xyz>
          <limit>
            <lower>0</lower>
            <upper>0</upper>
            <effort>1000</effort>
            <velocity>1</velocity>
          </limit>
          <dynamics>
            <damping>1</damping>
            <friction>0</friction>
            <spring_reference>0</spring_reference>
            <spring_stiffness>0</spring_stiffness>
          </dynamics>
          <use_parent_model_frame>1</use_parent_model_frame>
        </axis>
      </joint>
      <link name='COL_COL_COL_VIS_VIS_VIS_VIS_VIS_VIS_VIS_VIS_VIS_hollie_real.000'>
        <pose frame=''>0 -0.4 1.11 0 -0 1.62316</pose>
        <inertial>
          <pose frame=''>0 0 0 0 -0 0</pose>
          <mass>0.29364</mass>
          <inertia>
            <ixx>0.01</ixx>
            <ixy>0</ixy>
            <ixz>0</ixz>
            <iyy>0.01</iyy>
            <iyz>0</iyz>
            <izz>0.01</izz>
          </inertia>
        </inertial>
        <collision name='COL_COL_COL_VIS_VIS_VIS_VIS_VIS_VIS_VIS_VIS_VIS_hollie_real.000_collision'>
          <pose frame=''>0 0 1e-06 0 -0 0</pose>
          <geometry>
            <mesh>
              <scale>1 1 1</scale>
              <uri>model://arm_robot/collisions/COL_COL_COL_VIS_VIS_VIS_VIS_VIS_VIS_VIS_VIS_VIS_hollie_real.000.dae</uri>
            </mesh>
          </geometry>
          <max_contacts>10</max_contacts>
          <surface>
            <contact>
              <ode/>
            </contact>
            <bounce/>
            <friction>
              <ode/>
            </friction>
          </surface>
        </collision>
        <visual name='COL_COL_COL_VIS_VIS_VIS_VIS_VIS_VIS_VIS_VIS_VIS_hollie_real.000_visual'>
          <pose frame=''>0 0 1e-06 0 -0 0</pose>
          <geometry>
            <mesh>
              <scale>1 1 1</scale>
              <uri>model://arm_robot/meshes/VIS_COL_COL_VIS_VIS_VIS_VIS_VIS_VIS_VIS_VIS_VIS_hollie_real.000.dae</uri>
            </mesh>
          </geometry>
        </visual>
        <self_collide>0</self_collide>
        <kinematic>0</kinematic>
        <gravity>1</gravity>
      </link>
      <joint name='hollie_real_left_arm_1_joint' type='revolute'>
        <child>COL_COL_COL_VIS_VIS_VIS_VIS_VIS_VIS_VIS_VIS_VIS_hollie_real.000</child>
        <parent>hollie_real_left_arm_0_joint_link</parent>
        <axis>
          <xyz>0 0 1</xyz>
          <limit>
            <lower>-1.37255e+20</lower>
            <upper>1.37255e+20</upper>
            <effort>1000</effort>
            <velocity>1</velocity>
          </limit>
          <dynamics>
            <damping>1</damping>
            <friction>0</friction>
            <spring_reference>0</spring_reference>
            <spring_stiffness>0</spring_stiffness>
          </dynamics>
          <use_parent_model_frame>1</use_parent_model_frame>
        </axis>
      </joint>
      <link name='COL_COL_COL_VIS_VIS_VIS_VIS_VIS_VIS_VIS_VIS_VIS_hollie_real.001'>
        <pose frame=''>0 -0.4 1.11 1.5708 -0 1.62316</pose>
        <inertial>
          <pose frame=''>0 0 0 0 -0 0</pose>
          <mass>1.68311</mass>
          <inertia>
            <ixx>0.03</ixx>
            <ixy>0</ixy>
            <ixz>0</ixz>
            <iyy>0.03</iyy>
            <iyz>0</iyz>
            <izz>0.03</izz>
          </inertia>
        </inertial>
        <collision name='COL_COL_COL_VIS_VIS_VIS_VIS_VIS_VIS_VIS_VIS_VIS_hollie_real.001_collision'>
          <pose frame=''>-0 1e-06 -0 0 -0 0</pose>
          <geometry>
            <mesh>
              <scale>1 1 1</scale>
              <uri>model://arm_robot/collisions/COL_COL_COL_VIS_VIS_VIS_VIS_VIS_VIS_VIS_VIS_VIS_hollie_real.001.dae</uri>
            </mesh>
          </geometry>
          <max_contacts>10</max_contacts>
          <surface>
            <contact>
              <ode/>
            </contact>
            <bounce/>
            <friction>
              <ode/>
            </friction>
          </surface>
        </collision>
        <visual name='COL_COL_COL_VIS_VIS_VIS_VIS_VIS_VIS_VIS_VIS_VIS_hollie_real.001_visual'>
          <pose frame=''>-0 1e-06 -0 0 -0 0</pose>
          <geometry>
            <mesh>
              <scale>1 1 1</scale>
              <uri>model://arm_robot/meshes/VIS_COL_COL_VIS_VIS_VIS_VIS_VIS_VIS_VIS_VIS_VIS_hollie_real.001.dae</uri>
            </mesh>
          </geometry>
        </visual>
        <self_collide>0</self_collide>
        <kinematic>0</kinematic>
        <gravity>1</gravity>
      </link>
      <joint name='hollie_real_left_arm_2_joint' type='revolute'>
        <child>COL_COL_COL_VIS_VIS_VIS_VIS_VIS_VIS_VIS_VIS_VIS_hollie_real.001</child>
        <parent>COL_COL_COL_VIS_VIS_VIS_VIS_VIS_VIS_VIS_VIS_VIS_hollie_real.000</parent>
        <axis>
          <xyz>0.99863 0.052336 0</xyz>
          <limit>
            <lower>-2864.79</lower>
            <upper>2864.79</upper>
            <effort>1000</effort>
            <velocity>1</velocity>
          </limit>
          <dynamics>
            <damping>1</damping>
            <friction>0</friction>
            <spring_reference>0</spring_reference>
            <spring_stiffness>0</spring_stiffness>
          </dynamics>
          <use_parent_model_frame>1</use_parent_model_frame>
        </axis>
      </joint>
      <link name='COL_COL_COL_VIS_VIS_VIS_VIS_VIS_VIS_VIS_VIS_VIS_hollie_real.002'>
        <pose frame=''>0 -0.4 1.46 1.5708 -0 -1.51844</pose>
        <inertial>
          <pose frame=''>0 0 0 0 -0 0</pose>
          <mass>2.1</mass>
          <inertia>
            <ixx>0.03</ixx>
            <ixy>0</ixy>
            <ixz>0</ixz>
            <iyy>0.03</iyy>
            <iyz>0</iyz>
            <izz>0.03</izz>
          </inertia>
        </inertial>
        <collision name='COL_COL_COL_VIS_VIS_VIS_VIS_VIS_VIS_VIS_VIS_VIS_hollie_real.002_collision'>
          <pose frame=''>-0 1e-06 0 0 -0 0</pose>
          <geometry>
            <mesh>
              <scale>1 1 1</scale>
              <uri>model://arm_robot/collisions/COL_COL_COL_VIS_VIS_VIS_VIS_VIS_VIS_VIS_VIS_VIS_hollie_real.002.dae</uri>
            </mesh>
          </geometry>
          <max_contacts>10</max_contacts>
          <surface>
            <contact>
              <ode/>
            </contact>
            <bounce/>
            <friction>
              <ode/>
            </friction>
          </surface>
        </collision>
        <visual name='COL_COL_COL_VIS_VIS_VIS_VIS_VIS_VIS_VIS_VIS_VIS_hollie_real.002_visual'>
          <pose frame=''>-0 1e-06 0 0 -0 0</pose>
          <geometry>
            <mesh>
              <scale>1 1 1</scale>
              <uri>model://arm_robot/meshes/VIS_COL_COL_VIS_VIS_VIS_VIS_VIS_VIS_VIS_VIS_VIS_hollie_real.002.dae</uri>
            </mesh>
          </geometry>
        </visual>
        <self_collide>0</self_collide>
        <kinematic>0</kinematic>
        <gravity>1</gravity>
      </link>
      <joint name='hollie_real_left_arm_3_joint' type='revolute'>
        <child>COL_COL_COL_VIS_VIS_VIS_VIS_VIS_VIS_VIS_VIS_VIS_hollie_real.002</child>
        <parent>COL_COL_COL_VIS_VIS_VIS_VIS_VIS_VIS_VIS_VIS_VIS_hollie_real.001</parent>
        <axis>
          <xyz>-0.99863 -0.052336 0</xyz>
          <limit>
            <lower>-1.36749e+20</lower>
            <upper>1.36749e+20</upper>
            <effort>1000</effort>
            <velocity>1</velocity>
          </limit>
          <dynamics>
            <damping>1</damping>
            <friction>0</friction>
            <spring_reference>0</spring_reference>
            <spring_stiffness>0</spring_stiffness>
          </dynamics>
          <use_parent_model_frame>1</use_parent_model_frame>
        </axis>
      </joint>
      <link name='COL_COL_COL_VIS_VIS_VIS_VIS_VIS_VIS_VIS_VIS_VIS_hollie_real.003'>
        <pose frame=''>0 -0.4 1.46 0 -0 1.62316</pose>
        <inertial>
          <pose frame=''>0 0 0 0 -0 0</pose>
          <mass>1.68311</mass>
          <inertia>
            <ixx>0.03</ixx>
            <ixy>0</ixy>
            <ixz>0</ixz>
            <iyy>0.03</iyy>
            <iyz>0</iyz>
            <izz>0.03</izz>
          </inertia>
        </inertial>
        <collision name='COL_COL_COL_VIS_VIS_VIS_VIS_VIS_VIS_VIS_VIS_VIS_hollie_real.003_collision'>
          <pose frame=''>0 -0 0 0 -0 0</pose>
          <geometry>
            <mesh>
              <scale>1 1 1</scale>
              <uri>model://arm_robot/collisions/COL_COL_COL_VIS_VIS_VIS_VIS_VIS_VIS_VIS_VIS_VIS_hollie_real.003.dae</uri>
            </mesh>
          </geometry>
          <max_contacts>10</max_contacts>
          <surface>
            <contact>
              <ode/>
            </contact>
            <bounce/>
            <friction>
              <ode/>
            </friction>
          </surface>
        </collision>
        <visual name='COL_COL_COL_VIS_VIS_VIS_VIS_VIS_VIS_VIS_VIS_VIS_hollie_real.003_visual'>
          <pose frame=''>0 -0 0 0 -0 0</pose>
          <geometry>
            <mesh>
              <scale>1 1 1</scale>
              <uri>model://arm_robot/meshes/VIS_COL_COL_VIS_VIS_VIS_VIS_VIS_VIS_VIS_VIS_VIS_hollie_real.003.dae</uri>
            </mesh>
          </geometry>
        </visual>
        <self_collide>0</self_collide>
        <kinematic>0</kinematic>
        <gravity>1</gravity>
      </link>
      <joint name='hollie_real_left_arm_4_joint' type='revolute'>
        <child>COL_COL_COL_VIS_VIS_VIS_VIS_VIS_VIS_VIS_VIS_VIS_hollie_real.003</child>
        <parent>COL_COL_COL_VIS_VIS_VIS_VIS_VIS_VIS_VIS_VIS_VIS_hollie_real.002</parent>
        <axis>
          <xyz>0 0 1</xyz>
          <limit>
            <lower>-4.52188e+19</lower>
            <upper>4.52188e+19</upper>
            <effort>1000</effort>
            <velocity>1</velocity>
          </limit>
          <dynamics>
            <damping>1</damping>
            <friction>0</friction>
            <spring_reference>0</spring_reference>
            <spring_stiffness>0</spring_stiffness>
          </dynamics>
          <use_parent_model_frame>1</use_parent_model_frame>
        </axis>
      </joint>
      <link name='COL_COL_COL_VIS_VIS_VIS_VIS_VIS_VIS_VIS_VIS_VIS_hollie_real.004'>
        <pose frame=''>-0.005256 -0.400275 1.765 1.5708 -0 -1.51844</pose>
        <inertial>
          <pose frame=''>0 0 0 0 -0 0</pose>
          <mass>0.807</mass>
          <inertia>
            <ixx>0.03</ixx>
            <ixy>0</ixy>
            <ixz>0</ixz>
            <iyy>0.03</iyy>
            <iyz>0</iyz>
            <izz>0.03</izz>
          </inertia>
        </inertial>
        <collision name='COL_COL_COL_VIS_VIS_VIS_VIS_VIS_VIS_VIS_VIS_VIS_hollie_real.004_collision'>
          <pose frame=''>-0 1e-06 -0 0 -0 0</pose>
          <geometry>
            <mesh>
              <scale>1 1 1</scale>
              <uri>model://arm_robot/collisions/COL_COL_COL_VIS_VIS_VIS_VIS_VIS_VIS_VIS_VIS_VIS_hollie_real.004.dae</uri>
            </mesh>
          </geometry>
          <max_contacts>10</max_contacts>
          <surface>
            <contact>
              <ode/>
            </contact>
            <bounce/>
            <friction>
              <ode/>
            </friction>
          </surface>
        </collision>
        <visual name='COL_COL_COL_VIS_VIS_VIS_VIS_VIS_VIS_VIS_VIS_VIS_hollie_real.004_visual'>
          <pose frame=''>-0 1e-06 -0 1e-06 -2e-06 -0</pose>
          <geometry>
            <mesh>
              <scale>1 1 1</scale>
              <uri>model://arm_robot/meshes/VIS_COL_COL_VIS_VIS_VIS_VIS_VIS_VIS_VIS_VIS_VIS_hollie_real.004.dae</uri>
            </mesh>
          </geometry>
        </visual>
        <self_collide>0</self_collide>
        <kinematic>0</kinematic>
        <gravity>1</gravity>
      </link>
      <joint name='hollie_real_left_arm_5_joint' type='revolute'>
        <child>COL_COL_COL_VIS_VIS_VIS_VIS_VIS_VIS_VIS_VIS_VIS_hollie_real.004</child>
        <parent>COL_COL_COL_VIS_VIS_VIS_VIS_VIS_VIS_VIS_VIS_VIS_hollie_real.003</parent>
        <axis>
          <xyz>-0.99863 -0.052336 0</xyz>
          <limit>
            <lower>-1.36749e+20</lower>
            <upper>1.36749e+20</upper>
            <effort>1000</effort>
            <velocity>1</velocity>
          </limit>
          <dynamics>
            <damping>1</damping>
            <friction>0</friction>
            <spring_reference>0</spring_reference>
            <spring_stiffness>0</spring_stiffness>
          </dynamics>
          <use_parent_model_frame>1</use_parent_model_frame>
        </axis>
      </joint>
      <link name='COL_COL_COL_VIS_VIS_VIS_VIS_VIS_VIS_VIS_VIS_VIS_hollie_real.005'>
        <pose frame=''>-0.005256 -0.400275 1.765 0 0 -1.51844</pose>
        <inertial>
          <pose frame=''>0 0 0 0 -0 0</pose>
          <mass>0.819</mass>
          <inertia>
            <ixx>0.01</ixx>
            <ixy>0</ixy>
            <ixz>0</ixz>
            <iyy>0.01</iyy>
            <iyz>0</iyz>
            <izz>0.01</izz>
          </inertia>
        </inertial>
        <collision name='COL_COL_COL_VIS_VIS_VIS_VIS_VIS_VIS_VIS_VIS_VIS_hollie_real.005_collision'>
          <pose frame=''>-0 0 1e-06 0 -0 0</pose>
          <geometry>
            <mesh>
              <scale>1 1 1</scale>
              <uri>model://arm_robot/collisions/COL_COL_COL_VIS_VIS_VIS_VIS_VIS_VIS_VIS_VIS_VIS_hollie_real.005.dae</uri>
            </mesh>
          </geometry>
          <max_contacts>10</max_contacts>
          <surface>
            <contact>
              <ode/>
            </contact>
            <bounce/>
            <friction>
              <ode/>
            </friction>
          </surface>
        </collision>
        <visual name='COL_COL_COL_VIS_VIS_VIS_VIS_VIS_VIS_VIS_VIS_VIS_hollie_real.005_visual'>
          <pose frame=''>-0 0 1e-06 0 -0 0</pose>
          <geometry>
            <mesh>
              <scale>1 1 1</scale>
              <uri>model://arm_robot/meshes/VIS_COL_COL_VIS_VIS_VIS_VIS_VIS_VIS_VIS_VIS_VIS_hollie_real.005.dae</uri>
            </mesh>
          </geometry>
        </visual>
        <self_collide>0</self_collide>
        <kinematic>0</kinematic>
        <gravity>1</gravity>
      </link>
      <joint name='hollie_real_left_arm_6_joint' type='revolute'>
        <child>COL_COL_COL_VIS_VIS_VIS_VIS_VIS_VIS_VIS_VIS_VIS_hollie_real.005</child>
        <parent>COL_COL_COL_VIS_VIS_VIS_VIS_VIS_VIS_VIS_VIS_VIS_hollie_real.004</parent>
        <axis>
          <xyz>0 0 1</xyz>
          <limit>
            <lower>-4.52188e+19</lower>
            <upper>4.52188e+19</upper>
            <effort>1000</effort>
            <velocity>1</velocity>
          </limit>
          <dynamics>
            <damping>1</damping>
            <friction>0</friction>
            <spring_reference>0</spring_reference>
            <spring_stiffness>0</spring_stiffness>
          </dynamics>
          <use_parent_model_frame>1</use_parent_model_frame>
        </axis>
      </joint>
      <link name='COL_COL_COL_VIS_VIS_VIS_VIS_VIS_VIS_VIS_VIS_VIS_hollie_real.006'>
        <pose frame=''>-0.005256 -0.400276 1.865 0 0 -1.51844</pose>
        <inertial>
          <pose frame=''>0 0 0 0 -0 0</pose>
          <mass>1e-05</mass>
          <inertia>
            <ixx>0.01</ixx>
            <ixy>0</ixy>
            <ixz>0</ixz>
            <iyy>0.01</iyy>
            <iyz>0</iyz>
            <izz>0.01</izz>
          </inertia>
        </inertial>
        <collision name='COL_COL_COL_VIS_VIS_VIS_VIS_VIS_VIS_VIS_VIS_VIS_hollie_real.006_collision'>
          <pose frame=''>-0 1e-06 -0.031998 0 -0 0</pose>
          <geometry>
            <mesh>
              <scale>1 1 1</scale>
              <uri>model://arm_robot/collisions/COL_COL_COL_VIS_VIS_VIS_VIS_VIS_VIS_VIS_VIS_VIS_hollie_real.006.dae</uri>
            </mesh>
          </geometry>
          <max_contacts>10</max_contacts>
          <surface>
            <contact>
              <ode/>
            </contact>
            <bounce/>
            <friction>
              <ode/>
            </friction>
          </surface>
        </collision>
        <visual name='COL_COL_COL_VIS_VIS_VIS_VIS_VIS_VIS_VIS_VIS_VIS_hollie_real.006_visual'>
          <pose frame=''>-0 1e-06 -0.031998 0 -0 0</pose>
          <geometry>
            <mesh>
              <scale>1 1 1</scale>
              <uri>model://arm_robot/meshes/VIS_COL_COL_VIS_VIS_VIS_VIS_VIS_VIS_VIS_VIS_VIS_hollie_real.006.dae</uri>
            </mesh>
          </geometry>
        </visual>
        <self_collide>0</self_collide>
        <kinematic>0</kinematic>
        <gravity>1</gravity>
      </link>
      <joint name='hollie_real_left_hand_base_joint' type='prismatic'>
        <child>COL_COL_COL_VIS_VIS_VIS_VIS_VIS_VIS_VIS_VIS_VIS_hollie_real.006</child>
        <parent>COL_COL_COL_VIS_VIS_VIS_VIS_VIS_VIS_VIS_VIS_VIS_hollie_real.005</parent>
        <axis>
          <xyz>0.052336 -0.99863 -0</xyz>
          <limit>
            <lower>0</lower>
            <upper>0</upper>
            <effort>1000</effort>
            <velocity>1</velocity>
          </limit>
          <dynamics>
            <damping>1</damping>
            <friction>0</friction>
            <spring_reference>0</spring_reference>
            <spring_stiffness>0</spring_stiffness>
          </dynamics>
          <use_parent_model_frame>1</use_parent_model_frame>
        </axis>
      </joint>
      <link name='COL_COL_COL_VIS_VIS_VIS_VIS_VIS_VIS_VIS_VIS_VIS_hollie_real.007'>
        <pose frame=''>-0.018368 -0.400963 1.865 0 0 -1.51844</pose>
        <inertial>
          <pose frame=''>0 0 0 0 -0 0</pose>
          <mass>1e-05</mass>
          <inertia>
            <ixx>0.01</ixx>
            <ixy>0</ixy>
            <ixz>0</ixz>
            <iyy>0.01</iyy>
            <iyz>0</iyz>
            <izz>0.01</izz>
          </inertia>
        </inertial>
        <collision name='COL_COL_COL_VIS_VIS_VIS_VIS_VIS_VIS_VIS_VIS_VIS_hollie_real.007_collision'>
          <pose frame=''>-0 0.01313 2e-06 0 -0 0</pose>
          <geometry>
            <mesh>
              <scale>1 1 1</scale>
              <uri>model://arm_robot/collisions/COL_COL_COL_VIS_VIS_VIS_VIS_VIS_VIS_VIS_VIS_VIS_hollie_real.007.dae</uri>
            </mesh>
          </geometry>
          <max_contacts>10</max_contacts>
          <surface>
            <contact>
              <ode/>
            </contact>
            <bounce/>
            <friction>
              <ode/>
            </friction>
          </surface>
        </collision>
        <visual name='COL_COL_COL_VIS_VIS_VIS_VIS_VIS_VIS_VIS_VIS_VIS_hollie_real.007_visual'>
          <pose frame=''>-0 0.01313 2e-06 3.14159 0 -1e-06</pose>
          <geometry>
            <mesh>
              <scale>1 1 1</scale>
              <uri>model://arm_robot/meshes/VIS_COL_COL_VIS_VIS_VIS_VIS_VIS_VIS_VIS_VIS_VIS_hollie_real.007.dae</uri>
            </mesh>
          </geometry>
        </visual>
        <self_collide>0</self_collide>
        <kinematic>0</kinematic>
        <gravity>1</gravity>
      </link>
      <joint name='hollie_real_left_hand_f4' type='prismatic'>
        <child>COL_COL_COL_VIS_VIS_VIS_VIS_VIS_VIS_VIS_VIS_VIS_hollie_real.007</child>
        <parent>COL_COL_COL_VIS_VIS_VIS_VIS_VIS_VIS_VIS_VIS_VIS_hollie_real.006</parent>
        <axis>
          <xyz>0.052336 -0.99863 -0</xyz>
          <limit>
            <lower>0</lower>
            <upper>0</upper>
            <effort>1000</effort>
            <velocity>1</velocity>
          </limit>
          <dynamics>
            <damping>1</damping>
            <friction>0</friction>
            <spring_reference>0</spring_reference>
            <spring_stiffness>0</spring_stiffness>
          </dynamics>
          <use_parent_model_frame>1</use_parent_model_frame>
        </axis>
      </joint>
      <link name='COL_COL_COL_VIS_VIS_VIS_VIS_VIS_VIS_VIS_VIS_VIS_hollie_real.008'>
        <pose frame=''>0.008741 -0.416465 1.865 -0 0.261799 0.05236</pose>
        <inertial>
          <pose frame=''>0 0 0 0 -0 0</pose>
          <mass>1e-05</mass>
          <inertia>
            <ixx>0.01</ixx>
            <ixy>0</ixy>
            <ixz>0</ixz>
            <iyy>0.01</iyy>
            <iyz>0</iyz>
            <izz>0.01</izz>
          </inertia>
        </inertial>
        <collision name='COL_COL_COL_VIS_VIS_VIS_VIS_VIS_VIS_VIS_VIS_VIS_hollie_real.008_collision'>
          <pose frame=''>0 -1e-06 0.024418 0 -0 0</pose>
          <geometry>
            <mesh>
              <scale>1 1 1</scale>
              <uri>model://arm_robot/collisions/COL_COL_COL_VIS_VIS_VIS_VIS_VIS_VIS_VIS_VIS_VIS_hollie_real.008.dae</uri>
            </mesh>
          </geometry>
          <max_contacts>10</max_contacts>
          <surface>
            <contact>
              <ode/>
            </contact>
            <bounce/>
            <friction>
              <ode/>
            </friction>
          </surface>
        </collision>
        <visual name='COL_COL_COL_VIS_VIS_VIS_VIS_VIS_VIS_VIS_VIS_VIS_hollie_real.008_visual'>
          <pose frame=''>0 -1e-06 0.024418 3.14159 3e-06 3.14159</pose>
          <geometry>
            <mesh>
              <scale>1 1 1</scale>
              <uri>model://arm_robot/meshes/VIS_COL_COL_VIS_VIS_VIS_VIS_VIS_VIS_VIS_VIS_VIS_hollie_real.008.dae</uri>
            </mesh>
          </geometry>
        </visual>
        <self_collide>0</self_collide>
        <kinematic>0</kinematic>
        <gravity>1</gravity>
      </link>
      <joint name='hollie_real_left_hand_Thumb_Opposition' type='revolute'>
        <child>COL_COL_COL_VIS_VIS_VIS_VIS_VIS_VIS_VIS_VIS_VIS_hollie_real.008</child>
        <parent>COL_COL_COL_VIS_VIS_VIS_VIS_VIS_VIS_VIS_VIS_VIS_hollie_real.007</parent>
        <axis>
          <xyz>0.258464 0.013546 0.965926</xyz>
          <limit>
            <lower>0</lower>
            <upper>2.15805e+19</upper>
            <effort>1000</effort>
            <velocity>1</velocity>
          </limit>
          <dynamics>
            <damping>1</damping>
            <friction>0</friction>
            <spring_reference>0</spring_reference>
            <spring_stiffness>0</spring_stiffness>
          </dynamics>
          <use_parent_model_frame>1</use_parent_model_frame>
        </axis>
      </joint>
      <link name='hollie_real_left_hand_Thumb_Helper_link'>
        <pose frame=''>0.02062 -0.415843 1.90939 -3.14159 -1.309 0.05236</pose>
        <inertial>
          <pose frame=''>0 0 0 0 -0 0</pose>
          <mass>1e-05</mass>
          <inertia>
            <ixx>0.01</ixx>
            <ixy>0</ixy>
            <ixz>0</ixz>
            <iyy>0.01</iyy>
            <iyz>0</iyz>
            <izz>0.01</izz>
          </inertia>
        </inertial>
        <self_collide>0</self_collide>
        <kinematic>0</kinematic>
        <gravity>1</gravity>
      </link>
      <joint name='hollie_real_left_hand_Thumb_Helper' type='prismatic'>
        <child>hollie_real_left_hand_Thumb_Helper_link</child>
        <parent>COL_COL_COL_VIS_VIS_VIS_VIS_VIS_VIS_VIS_VIS_VIS_hollie_real.008</parent>
        <axis>
          <xyz>0.258465 0.013546 0.965926</xyz>
          <limit>
            <lower>0</lower>
            <upper>0</upper>
            <effort>1000</effort>
            <velocity>1</velocity>
          </limit>
          <dynamics>
            <damping>1</damping>
            <friction>0</friction>
            <spring_reference>0</spring_reference>
            <spring_stiffness>0</spring_stiffness>
          </dynamics>
          <use_parent_model_frame>1</use_parent_model_frame>
        </axis>
      </joint>
      <link name='COL_COL_COL_VIS_VIS_VIS_VIS_VIS_VIS_VIS_VIS_VIS_hollie_real.009'>
        <pose frame=''>0.02062 -0.415843 1.90939 -1.8834 -0.570602 -1.3456</pose>
        <inertial>
          <pose frame=''>0 0 0 0 -0 0</pose>
          <mass>1e-05</mass>
          <inertia>
            <ixx>0.01</ixx>
            <ixy>0</ixy>
            <ixz>0</ixz>
            <iyy>0.01</iyy>
            <iyz>0</iyz>
            <izz>0.01</izz>
          </inertia>
        </inertial>
        <collision name='COL_COL_COL_VIS_VIS_VIS_VIS_VIS_VIS_VIS_VIS_VIS_hollie_real.009_collision'>
          <pose frame=''>1e-06 0 -0 0 -0 0</pose>
          <geometry>
            <mesh>
              <scale>1 1 1</scale>
              <uri>model://arm_robot/collisions/COL_COL_COL_VIS_VIS_VIS_VIS_VIS_VIS_VIS_VIS_VIS_hollie_real.009.dae</uri>
            </mesh>
          </geometry>
          <max_contacts>10</max_contacts>
          <surface>
            <contact>
              <ode/>
            </contact>
            <bounce/>
            <friction>
              <ode/>
            </friction>
          </surface>
        </collision>
        <visual name='COL_COL_COL_VIS_VIS_VIS_VIS_VIS_VIS_VIS_VIS_VIS_hollie_real.009_visual'>
          <pose frame=''>1e-06 0 -0 -3.14159 0 1e-06</pose>
          <geometry>
            <mesh>
              <scale>1 1 1</scale>
              <uri>model://arm_robot/meshes/VIS_COL_COL_VIS_VIS_VIS_VIS_VIS_VIS_VIS_VIS_VIS_hollie_real.009.dae</uri>
            </mesh>
          </geometry>
        </visual>
        <self_collide>0</self_collide>
        <kinematic>0</kinematic>
        <gravity>1</gravity>
      </link>
      <joint name='hollie_real_left_hand_Thumb_Flexion' type='revolute'>
        <child>COL_COL_COL_VIS_VIS_VIS_VIS_VIS_VIS_VIS_VIS_VIS_hollie_real.009</child>
        <parent>hollie_real_left_hand_Thumb_Helper_link</parent>
        <axis>
          <xyz>0.964602 0.050553 -0.258819</xyz>
          <limit>
            <lower>0</lower>
            <upper>2.11982e+19</upper>
            <effort>1000</effort>
            <velocity>1</velocity>
          </limit>
          <dynamics>
            <damping>1</damping>
            <friction>0</friction>
            <spring_reference>0</spring_reference>
            <spring_stiffness>0</spring_stiffness>
          </dynamics>
          <use_parent_model_frame>1</use_parent_model_frame>
        </axis>
      </joint>
      <link name='COL_COL_COL_VIS_VIS_VIS_VIS_VIS_VIS_VIS_VIS_VIS_hollie_real.010'>
        <pose frame=''>0.029734 -0.455628 1.93559 -1.8834 -0.570602 -1.3456</pose>
        <inertial>
          <pose frame=''>0 0 0 0 -0 0</pose>
          <mass>1e-05</mass>
          <inertia>
            <ixx>0.01</ixx>
            <ixy>0</ixy>
            <ixz>0</ixz>
            <iyy>0.01</iyy>
            <iyz>0</iyz>
            <izz>0.01</izz>
          </inertia>
        </inertial>
        <collision name='COL_COL_COL_VIS_VIS_VIS_VIS_VIS_VIS_VIS_VIS_VIS_hollie_real.010_collision'>
          <pose frame=''>-1e-06 -1e-06 0 0 -0 0</pose>
          <geometry>
            <mesh>
              <scale>1 1 1</scale>
              <uri>model://arm_robot/collisions/COL_COL_COL_VIS_VIS_VIS_VIS_VIS_VIS_VIS_VIS_VIS_hollie_real.010.dae</uri>
            </mesh>
          </geometry>
          <max_contacts>10</max_contacts>
          <surface>
            <contact>
              <ode/>
            </contact>
            <bounce/>
            <friction>
              <ode/>
            </friction>
          </surface>
        </collision>
        <visual name='COL_COL_COL_VIS_VIS_VIS_VIS_VIS_VIS_VIS_VIS_VIS_hollie_real.010_visual'>
          <pose frame=''>-1e-06 -1e-06 0 3.14159 -0 2e-06</pose>
          <geometry>
            <mesh>
              <scale>1 1 1</scale>
              <uri>model://arm_robot/meshes/VIS_COL_COL_VIS_VIS_VIS_VIS_VIS_VIS_VIS_VIS_VIS_hollie_real.010.dae</uri>
            </mesh>
          </geometry>
        </visual>
        <self_collide>0</self_collide>
        <kinematic>0</kinematic>
        <gravity>1</gravity>
      </link>
      <joint name='hollie_real_left_hand_j3' type='revolute'>
        <child>COL_COL_COL_VIS_VIS_VIS_VIS_VIS_VIS_VIS_VIS_VIS_hollie_real.010</child>
        <parent>COL_COL_COL_VIS_VIS_VIS_VIS_VIS_VIS_VIS_VIS_VIS_hollie_real.009</parent>
        <axis>
          <xyz>0.964602 0.050553 -0.258819</xyz>
          <limit>
            <lower>0</lower>
            <upper>2.15185e+19</upper>
            <effort>1000</effort>
            <velocity>1</velocity>
          </limit>
          <dynamics>
            <damping>1</damping>
            <friction>0</friction>
            <spring_reference>0</spring_reference>
            <spring_stiffness>0</spring_stiffness>
          </dynamics>
          <use_parent_model_frame>1</use_parent_model_frame>
        </axis>
      </joint>
      <link name='COL_COL_COL_VIS_VIS_VIS_VIS_VIS_VIS_VIS_VIS_VIS_hollie_real.011'>
        <pose frame=''>0.035372 -0.480238 1.95179 -1.8834 -0.570602 -1.3456</pose>
        <inertial>
          <pose frame=''>0 0 0 0 -0 0</pose>
          <mass>1e-05</mass>
          <inertia>
            <ixx>0.01</ixx>
            <ixy>0</ixy>
            <ixz>0</ixz>
            <iyy>0.01</iyy>
            <iyz>0</iyz>
            <izz>0.01</izz>
          </inertia>
        </inertial>
        <collision name='COL_COL_COL_VIS_VIS_VIS_VIS_VIS_VIS_VIS_VIS_VIS_hollie_real.011_collision'>
          <pose frame=''>-0 -0 -0 0 -0 0</pose>
          <geometry>
            <mesh>
              <scale>1 1 1</scale>
              <uri>model://arm_robot/collisions/COL_COL_COL_VIS_VIS_VIS_VIS_VIS_VIS_VIS_VIS_VIS_hollie_real.011.dae</uri>
            </mesh>
          </geometry>
          <max_contacts>10</max_contacts>
          <surface>
            <contact>
              <ode/>
            </contact>
            <bounce/>
            <friction>
              <ode/>
            </friction>
          </surface>
        </collision>
        <visual name='COL_COL_COL_VIS_VIS_VIS_VIS_VIS_VIS_VIS_VIS_VIS_hollie_real.011_visual'>
          <pose frame=''>-0 -0 -0 3.14159 -0 2e-06</pose>
          <geometry>
            <mesh>
              <scale>1 1 1</scale>
              <uri>model://arm_robot/meshes/VIS_COL_COL_VIS_VIS_VIS_VIS_VIS_VIS_VIS_VIS_VIS_hollie_real.011.dae</uri>
            </mesh>
          </geometry>
        </visual>
        <self_collide>0</self_collide>
        <kinematic>0</kinematic>
        <gravity>1</gravity>
      </link>
      <joint name='hollie_real_left_hand_j4' type='revolute'>
        <child>COL_COL_COL_VIS_VIS_VIS_VIS_VIS_VIS_VIS_VIS_VIS_hollie_real.011</child>
        <parent>COL_COL_COL_VIS_VIS_VIS_VIS_VIS_VIS_VIS_VIS_VIS_hollie_real.010</parent>
        <axis>
          <xyz>0.964602 0.050553 -0.258819</xyz>
          <limit>
            <lower>0</lower>
            <upper>3.07139e+19</upper>
            <effort>1000</effort>
            <velocity>1</velocity>
          </limit>
          <dynamics>
            <damping>1</damping>
            <friction>0</friction>
            <spring_reference>0</spring_reference>
            <spring_stiffness>0</spring_stiffness>
          </dynamics>
          <use_parent_model_frame>1</use_parent_model_frame>
        </axis>
      </joint>
      <link name='hollie_real_left_hand_f1_link'>
        <pose frame=''>-0.018368 -0.400963 1.865 0 0 -1.51844</pose>
        <inertial>
          <pose frame=''>0 0 0 0 -0 0</pose>
          <mass>1e-05</mass>
          <inertia>
            <ixx>0.01</ixx>
            <ixy>0</ixy>
            <ixz>0</ixz>
            <iyy>0.01</iyy>
            <iyz>0</iyz>
            <izz>0.01</izz>
          </inertia>
        </inertial>
        <self_collide>0</self_collide>
        <kinematic>0</kinematic>
        <gravity>1</gravity>
      </link>
      <joint name='hollie_real_left_hand_f1' type='prismatic'>
        <child>hollie_real_left_hand_f1_link</child>
        <parent>COL_COL_COL_VIS_VIS_VIS_VIS_VIS_VIS_VIS_VIS_VIS_hollie_real.007</parent>
        <axis>
          <xyz>0.052336 -0.99863 -0</xyz>
          <limit>
            <lower>0</lower>
            <upper>0</upper>
            <effort>1000</effort>
            <velocity>1</velocity>
          </limit>
          <dynamics>
            <damping>1</damping>
            <friction>0</friction>
            <spring_reference>0</spring_reference>
            <spring_stiffness>0</spring_stiffness>
          </dynamics>
          <use_parent_model_frame>1</use_parent_model_frame>
        </axis>
      </joint>
      <link name='hollie_real_left_hand_f2_link'>
        <pose frame=''>-0.018368 -0.400963 1.865 0 0 -1.51844</pose>
        <inertial>
          <pose frame=''>0 0 0 0 -0 0</pose>
          <mass>1e-05</mass>
          <inertia>
            <ixx>0.01</ixx>
            <ixy>0</ixy>
            <ixz>0</ixz>
            <iyy>0.01</iyy>
            <iyz>0</iyz>
            <izz>0.01</izz>
          </inertia>
        </inertial>
        <self_collide>0</self_collide>
        <kinematic>0</kinematic>
        <gravity>1</gravity>
      </link>
      <joint name='hollie_real_left_hand_f2' type='prismatic'>
        <child>hollie_real_left_hand_f2_link</child>
        <parent>hollie_real_left_hand_f1_link</parent>
        <axis>
          <xyz>0.052336 -0.99863 -0</xyz>
          <limit>
            <lower>0</lower>
            <upper>0</upper>
            <effort>1000</effort>
            <velocity>1</velocity>
          </limit>
          <dynamics>
            <damping>1</damping>
            <friction>0</friction>
            <spring_reference>0</spring_reference>
            <spring_stiffness>0</spring_stiffness>
          </dynamics>
          <use_parent_model_frame>1</use_parent_model_frame>
        </axis>
      </joint>
      <link name='hollie_real_left_hand_f3_link'>
        <pose frame=''>-0.018368 -0.400963 1.865 0 0 -1.51844</pose>
        <inertial>
          <pose frame=''>0 0 0 0 -0 0</pose>
          <mass>1e-05</mass>
          <inertia>
            <ixx>0.01</ixx>
            <ixy>0</ixy>
            <ixz>0</ixz>
            <iyy>0.01</iyy>
            <iyz>0</iyz>
            <izz>0.01</izz>
          </inertia>
        </inertial>
        <self_collide>0</self_collide>
        <kinematic>0</kinematic>
        <gravity>1</gravity>
      </link>
      <joint name='hollie_real_left_hand_f3' type='prismatic'>
        <child>hollie_real_left_hand_f3_link</child>
        <parent>hollie_real_left_hand_f2_link</parent>
        <axis>
          <xyz>0.052336 -0.99863 -0</xyz>
          <limit>
            <lower>0</lower>
            <upper>0</upper>
            <effort>1000</effort>
            <velocity>1</velocity>
          </limit>
          <dynamics>
            <damping>1</damping>
            <friction>0</friction>
            <spring_reference>0</spring_reference>
            <spring_stiffness>0</spring_stiffness>
          </dynamics>
          <use_parent_model_frame>1</use_parent_model_frame>
        </axis>
      </joint>
      <link name='COL_COL_COL_VIS_VIS_VIS_VIS_VIS_VIS_VIS_VIS_VIS_hollie_real.012'>
        <pose frame=''>-0.017059 -0.425928 1.975 -1.93916 -1.57079 1.99152</pose>
        <inertial>
          <pose frame=''>0 0 0 0 -0 0</pose>
          <mass>1e-05</mass>
          <inertia>
            <ixx>0.01</ixx>
            <ixy>0</ixy>
            <ixz>0</ixz>
            <iyy>0.01</iyy>
            <iyz>0</iyz>
            <izz>0.01</izz>
          </inertia>
        </inertial>
        <collision name='COL_COL_COL_VIS_VIS_VIS_VIS_VIS_VIS_VIS_VIS_VIS_hollie_real.012_collision'>
          <pose frame=''>0 -0 0.01321 0 -0 0</pose>
          <geometry>
            <mesh>
              <scale>1 1 1</scale>
              <uri>model://arm_robot/collisions/COL_COL_COL_VIS_VIS_VIS_VIS_VIS_VIS_VIS_VIS_VIS_hollie_real.012.dae</uri>
            </mesh>
          </geometry>
          <max_contacts>10</max_contacts>
          <surface>
            <contact>
              <ode/>
            </contact>
            <bounce/>
            <friction>
              <ode/>
            </friction>
          </surface>
        </collision>
        <visual name='COL_COL_COL_VIS_VIS_VIS_VIS_VIS_VIS_VIS_VIS_VIS_hollie_real.012_visual'>
          <pose frame=''>0 -0 0.01321 0 -0 0</pose>
          <geometry>
            <mesh>
              <scale>1 1 1</scale>
              <uri>model://arm_robot/meshes/VIS_COL_COL_VIS_VIS_VIS_VIS_VIS_VIS_VIS_VIS_VIS_hollie_real.012.dae</uri>
            </mesh>
          </geometry>
        </visual>
        <self_collide>0</self_collide>
        <kinematic>0</kinematic>
        <gravity>1</gravity>
      </link>
      <joint name='hollie_real_left_hand_index_spread' type='revolute'>
        <child>COL_COL_COL_VIS_VIS_VIS_VIS_VIS_VIS_VIS_VIS_VIS_hollie_real.012</child>
        <parent>hollie_real_left_hand_f3_link</parent>
        <axis>
          <xyz>-0.99863 -0.052336 0</xyz>
          <limit>
            <lower>0</lower>
            <upper>6.29852e+18</upper>
            <effort>1000</effort>
            <velocity>1</velocity>
          </limit>
          <dynamics>
            <damping>1</damping>
            <friction>0</friction>
            <spring_reference>0</spring_reference>
            <spring_stiffness>0</spring_stiffness>
          </dynamics>
          <use_parent_model_frame>1</use_parent_model_frame>
        </axis>
      </joint>
      <link name='COL_COL_COL_VIS_VIS_VIS_VIS_VIS_VIS_VIS_VIS_VIS_hollie_real.013'>
        <pose frame=''>-0.017059 -0.425928 1.975 2.77323 -1.57079 1.99152</pose>
        <inertial>
          <pose frame=''>0 0 0 0 -0 0</pose>
          <mass>1e-05</mass>
          <inertia>
            <ixx>0.01</ixx>
            <ixy>0</ixy>
            <ixz>0</ixz>
            <iyy>0.01</iyy>
            <iyz>0</iyz>
            <izz>0.01</izz>
          </inertia>
        </inertial>
        <collision name='COL_COL_COL_VIS_VIS_VIS_VIS_VIS_VIS_VIS_VIS_VIS_hollie_real.013_collision'>
          <pose frame=''>-1e-06 0 0 0 -0 0</pose>
          <geometry>
            <mesh>
              <scale>1 1 1</scale>
              <uri>model://arm_robot/collisions/COL_COL_COL_VIS_VIS_VIS_VIS_VIS_VIS_VIS_VIS_VIS_hollie_real.013.dae</uri>
            </mesh>
          </geometry>
          <max_contacts>10</max_contacts>
          <surface>
            <contact>
              <ode/>
            </contact>
            <bounce/>
            <friction>
              <ode/>
            </friction>
          </surface>
        </collision>
        <visual name='COL_COL_COL_VIS_VIS_VIS_VIS_VIS_VIS_VIS_VIS_VIS_hollie_real.013_visual'>
          <pose frame=''>-1e-06 0 0 -3e-06 -0 0</pose>
          <geometry>
            <mesh>
              <scale>1 1 1</scale>
              <uri>model://arm_robot/meshes/VIS_COL_COL_VIS_VIS_VIS_VIS_VIS_VIS_VIS_VIS_VIS_hollie_real.013.dae</uri>
            </mesh>
          </geometry>
        </visual>
        <self_collide>0</self_collide>
        <kinematic>0</kinematic>
        <gravity>1</gravity>
      </link>
      <joint name='hollie_real_left_hand_Index_Finger_Proximal' type='revolute'>
        <child>COL_COL_COL_VIS_VIS_VIS_VIS_VIS_VIS_VIS_VIS_VIS_hollie_real.013</child>
        <parent>COL_COL_COL_VIS_VIS_VIS_VIS_VIS_VIS_VIS_VIS_VIS_hollie_real.012</parent>
        <axis>
          <xyz>-0.052336 0.99863 0</xyz>
          <limit>
            <lower>0</lower>
            <upper>1.74429e+19</upper>
            <effort>1000</effort>
            <velocity>1</velocity>
          </limit>
          <dynamics>
            <damping>1</damping>
            <friction>0</friction>
            <spring_reference>0</spring_reference>
            <spring_stiffness>0</spring_stiffness>
          </dynamics>
          <use_parent_model_frame>1</use_parent_model_frame>
        </axis>
      </joint>
      <link name='COL_COL_COL_VIS_VIS_VIS_VIS_VIS_VIS_VIS_VIS_VIS_hollie_real.014'>
        <pose frame=''>-0.017059 -0.425928 2.02304 2.77323 -1.57079 1.99152</pose>
        <inertial>
          <pose frame=''>0 0 0 0 -0 0</pose>
          <mass>1e-05</mass>
          <inertia>
            <ixx>0.01</ixx>
            <ixy>0</ixy>
            <ixz>0</ixz>
            <iyy>0.01</iyy>
            <iyz>0</iyz>
            <izz>0.01</izz>
          </inertia>
        </inertial>
        <collision name='COL_COL_COL_VIS_VIS_VIS_VIS_VIS_VIS_VIS_VIS_VIS_hollie_real.014_collision'>
          <pose frame=''>-0 -0 0 0 -0 0</pose>
          <geometry>
            <mesh>
              <scale>1 1 1</scale>
              <uri>model://arm_robot/collisions/COL_COL_COL_VIS_VIS_VIS_VIS_VIS_VIS_VIS_VIS_VIS_hollie_real.014.dae</uri>
            </mesh>
          </geometry>
          <max_contacts>10</max_contacts>
          <surface>
            <contact>
              <ode/>
            </contact>
            <bounce/>
            <friction>
              <ode/>
            </friction>
          </surface>
        </collision>
        <visual name='COL_COL_COL_VIS_VIS_VIS_VIS_VIS_VIS_VIS_VIS_VIS_hollie_real.014_visual'>
          <pose frame=''>-0 -0 0 -2e-06 0 0</pose>
          <geometry>
            <mesh>
              <scale>1 1 1</scale>
              <uri>model://arm_robot/meshes/VIS_COL_COL_VIS_VIS_VIS_VIS_VIS_VIS_VIS_VIS_VIS_hollie_real.014.dae</uri>
            </mesh>
          </geometry>
        </visual>
        <self_collide>0</self_collide>
        <kinematic>0</kinematic>
        <gravity>1</gravity>
      </link>
      <joint name='hollie_real_left_hand_Index_Finger_Distal' type='revolute'>
        <child>COL_COL_COL_VIS_VIS_VIS_VIS_VIS_VIS_VIS_VIS_VIS_hollie_real.014</child>
        <parent>COL_COL_COL_VIS_VIS_VIS_VIS_VIS_VIS_VIS_VIS_VIS_hollie_real.013</parent>
        <axis>
          <xyz>-0.052336 0.99863 0</xyz>
          <limit>
            <lower>0</lower>
            <upper>2.9141e+19</upper>
            <effort>1000</effort>
            <velocity>1</velocity>
          </limit>
          <dynamics>
            <damping>1</damping>
            <friction>0</friction>
            <spring_reference>0</spring_reference>
            <spring_stiffness>0</spring_stiffness>
          </dynamics>
          <use_parent_model_frame>1</use_parent_model_frame>
        </axis>
      </joint>
      <link name='COL_COL_COL_VIS_VIS_VIS_VIS_VIS_VIS_VIS_VIS_VIS_hollie_real.015'>
        <pose frame=''>-0.017059 -0.425928 2.04904 2.77323 -1.57079 1.99152</pose>
        <inertial>
          <pose frame=''>0 0 0 0 -0 0</pose>
          <mass>1e-05</mass>
          <inertia>
            <ixx>0.01</ixx>
            <ixy>0</ixy>
            <ixz>0</ixz>
            <iyy>0.01</iyy>
            <iyz>0</iyz>
            <izz>0.01</izz>
          </inertia>
        </inertial>
        <collision name='COL_COL_COL_VIS_VIS_VIS_VIS_VIS_VIS_VIS_VIS_VIS_hollie_real.015_collision'>
          <pose frame=''>-0 0 -0 0 -0 0</pose>
          <geometry>
            <mesh>
              <scale>1 1 1</scale>
              <uri>model://arm_robot/collisions/COL_COL_COL_VIS_VIS_VIS_VIS_VIS_VIS_VIS_VIS_VIS_hollie_real.015.dae</uri>
            </mesh>
          </geometry>
          <max_contacts>10</max_contacts>
          <surface>
            <contact>
              <ode/>
            </contact>
            <bounce/>
            <friction>
              <ode/>
            </friction>
          </surface>
        </collision>
        <visual name='COL_COL_COL_VIS_VIS_VIS_VIS_VIS_VIS_VIS_VIS_VIS_hollie_real.015_visual'>
          <pose frame=''>-0 0 -0 -3e-06 0 0</pose>
          <geometry>
            <mesh>
              <scale>1 1 1</scale>
              <uri>model://arm_robot/meshes/VIS_COL_COL_VIS_VIS_VIS_VIS_VIS_VIS_VIS_VIS_VIS_hollie_real.015.dae</uri>
            </mesh>
          </geometry>
        </visual>
        <self_collide>0</self_collide>
        <kinematic>0</kinematic>
        <gravity>1</gravity>
      </link>
      <joint name='hollie_real_left_hand_j14' type='revolute'>
        <child>COL_COL_COL_VIS_VIS_VIS_VIS_VIS_VIS_VIS_VIS_VIS_hollie_real.015</child>
        <parent>COL_COL_COL_VIS_VIS_VIS_VIS_VIS_VIS_VIS_VIS_VIS_hollie_real.014</parent>
        <axis>
          <xyz>-0.052336 0.99863 0</xyz>
          <limit>
            <lower>0</lower>
            <upper>3.04517e+19</upper>
            <effort>1000</effort>
            <velocity>1</velocity>
          </limit>
          <dynamics>
            <damping>1</damping>
            <friction>0</friction>
            <spring_reference>0</spring_reference>
            <spring_stiffness>0</spring_stiffness>
          </dynamics>
          <use_parent_model_frame>1</use_parent_model_frame>
        </axis>
      </joint>
      <link name='COL_COL_COL_VIS_VIS_VIS_VIS_VIS_VIS_VIS_VIS_VIS_hollie_real.016'>
        <pose frame=''>-0.018368 -0.400963 1.975 -1.93916 -1.57079 1.99152</pose>
        <inertial>
          <pose frame=''>0 0 0 0 -0 0</pose>
          <mass>1e-05</mass>
          <inertia>
            <ixx>0.01</ixx>
            <ixy>0</ixy>
            <ixz>0</ixz>
            <iyy>0.01</iyy>
            <iyz>0</iyz>
            <izz>0.01</izz>
          </inertia>
        </inertial>
        <collision name='COL_COL_COL_VIS_VIS_VIS_VIS_VIS_VIS_VIS_VIS_VIS_hollie_real.016_collision'>
          <pose frame=''>-0 -1e-06 0.01321 0 -0 0</pose>
          <geometry>
            <mesh>
              <scale>1 1 1</scale>
              <uri>model://arm_robot/collisions/COL_COL_COL_VIS_VIS_VIS_VIS_VIS_VIS_VIS_VIS_VIS_hollie_real.016.dae</uri>
            </mesh>
          </geometry>
          <max_contacts>10</max_contacts>
          <surface>
            <contact>
              <ode/>
            </contact>
            <bounce/>
            <friction>
              <ode/>
            </friction>
          </surface>
        </collision>
        <visual name='COL_COL_COL_VIS_VIS_VIS_VIS_VIS_VIS_VIS_VIS_VIS_hollie_real.016_visual'>
          <pose frame=''>-0 -1e-06 0.01321 0 -0 0</pose>
          <geometry>
            <mesh>
              <scale>1 1 1</scale>
              <uri>model://arm_robot/meshes/VIS_COL_COL_VIS_VIS_VIS_VIS_VIS_VIS_VIS_VIS_VIS_hollie_real.016.dae</uri>
            </mesh>
          </geometry>
        </visual>
        <self_collide>0</self_collide>
        <kinematic>0</kinematic>
        <gravity>1</gravity>
      </link>
      <joint name='hollie_real_left_hand_middle_spread_dummy' type='prismatic'>
        <child>COL_COL_COL_VIS_VIS_VIS_VIS_VIS_VIS_VIS_VIS_VIS_hollie_real.016</child>
        <parent>hollie_real_left_hand_f1_link</parent>
        <axis>
          <xyz>0 -0 1</xyz>
          <limit>
            <lower>0</lower>
            <upper>0</upper>
            <effort>1000</effort>
            <velocity>1</velocity>
          </limit>
          <dynamics>
            <damping>1</damping>
            <friction>0</friction>
            <spring_reference>0</spring_reference>
            <spring_stiffness>0</spring_stiffness>
          </dynamics>
          <use_parent_model_frame>1</use_parent_model_frame>
        </axis>
      </joint>
      <link name='COL_COL_COL_VIS_VIS_VIS_VIS_VIS_VIS_VIS_VIS_VIS_hollie_real.017'>
        <pose frame=''>-0.018368 -0.400963 1.975 2.77323 -1.57079 1.99152</pose>
        <inertial>
          <pose frame=''>0 0 0 0 -0 0</pose>
          <mass>1e-05</mass>
          <inertia>
            <ixx>0.01</ixx>
            <ixy>0</ixy>
            <ixz>0</ixz>
            <iyy>0.01</iyy>
            <iyz>0</iyz>
            <izz>0.01</izz>
          </inertia>
        </inertial>
        <collision name='COL_COL_COL_VIS_VIS_VIS_VIS_VIS_VIS_VIS_VIS_VIS_hollie_real.017_collision'>
          <pose frame=''>-0 0 -1e-06 0 -0 0</pose>
          <geometry>
            <mesh>
              <scale>1 1 1</scale>
              <uri>model://arm_robot/collisions/COL_COL_COL_VIS_VIS_VIS_VIS_VIS_VIS_VIS_VIS_VIS_hollie_real.017.dae</uri>
            </mesh>
          </geometry>
          <max_contacts>10</max_contacts>
          <surface>
            <contact>
              <ode/>
            </contact>
            <bounce/>
            <friction>
              <ode/>
            </friction>
          </surface>
        </collision>
        <visual name='COL_COL_COL_VIS_VIS_VIS_VIS_VIS_VIS_VIS_VIS_VIS_hollie_real.017_visual'>
          <pose frame=''>-0 0 -1e-06 1e-06 -0 0</pose>
          <geometry>
            <mesh>
              <scale>1 1 1</scale>
              <uri>model://arm_robot/meshes/VIS_COL_COL_VIS_VIS_VIS_VIS_VIS_VIS_VIS_VIS_VIS_hollie_real.017.dae</uri>
            </mesh>
          </geometry>
        </visual>
        <self_collide>0</self_collide>
        <kinematic>0</kinematic>
        <gravity>1</gravity>
      </link>
      <joint name='hollie_real_left_hand_Middle_Finger_Proximal' type='revolute'>
        <child>COL_COL_COL_VIS_VIS_VIS_VIS_VIS_VIS_VIS_VIS_VIS_hollie_real.017</child>
        <parent>COL_COL_COL_VIS_VIS_VIS_VIS_VIS_VIS_VIS_VIS_VIS_hollie_real.016</parent>
        <axis>
          <xyz>-0.052336 0.99863 0</xyz>
          <limit>
            <lower>0</lower>
            <upper>1.74429e+19</upper>
            <effort>1000</effort>
            <velocity>1</velocity>
          </limit>
          <dynamics>
            <damping>1</damping>
            <friction>0</friction>
            <spring_reference>0</spring_reference>
            <spring_stiffness>0</spring_stiffness>
          </dynamics>
          <use_parent_model_frame>1</use_parent_model_frame>
        </axis>
      </joint>
      <link name='COL_COL_COL_VIS_VIS_VIS_VIS_VIS_VIS_VIS_VIS_VIS_hollie_real.018'>
        <pose frame=''>-0.018368 -0.400963 2.02504 2.77323 -1.57079 1.99152</pose>
        <inertial>
          <pose frame=''>0 0 0 0 -0 0</pose>
          <mass>1e-05</mass>
          <inertia>
            <ixx>0.01</ixx>
            <ixy>0</ixy>
            <ixz>0</ixz>
            <iyy>0.01</iyy>
            <iyz>0</iyz>
            <izz>0.01</izz>
          </inertia>
        </inertial>
        <collision name='COL_COL_COL_VIS_VIS_VIS_VIS_VIS_VIS_VIS_VIS_VIS_hollie_real.018_collision'>
          <pose frame=''>-1e-06 1e-06 -0 0 -0 0</pose>
          <geometry>
            <mesh>
              <scale>1 1 1</scale>
              <uri>model://arm_robot/collisions/COL_COL_COL_VIS_VIS_VIS_VIS_VIS_VIS_VIS_VIS_VIS_hollie_real.018.dae</uri>
            </mesh>
          </geometry>
          <max_contacts>10</max_contacts>
          <surface>
            <contact>
              <ode/>
            </contact>
            <bounce/>
            <friction>
              <ode/>
            </friction>
          </surface>
        </collision>
        <visual name='COL_COL_COL_VIS_VIS_VIS_VIS_VIS_VIS_VIS_VIS_VIS_hollie_real.018_visual'>
          <pose frame=''>-1e-06 1e-06 -0 0 -0 0</pose>
          <geometry>
            <mesh>
              <scale>1 1 1</scale>
              <uri>model://arm_robot/meshes/VIS_COL_COL_VIS_VIS_VIS_VIS_VIS_VIS_VIS_VIS_VIS_hollie_real.018.dae</uri>
            </mesh>
          </geometry>
        </visual>
        <self_collide>0</self_collide>
        <kinematic>0</kinematic>
        <gravity>1</gravity>
      </link>
      <joint name='hollie_real_left_hand_Middle_Finger_Distal' type='revolute'>
        <child>COL_COL_COL_VIS_VIS_VIS_VIS_VIS_VIS_VIS_VIS_VIS_hollie_real.018</child>
        <parent>COL_COL_COL_VIS_VIS_VIS_VIS_VIS_VIS_VIS_VIS_VIS_hollie_real.017</parent>
        <axis>
          <xyz>-0.052336 0.99863 0</xyz>
          <limit>
            <lower>0</lower>
            <upper>2.9141e+19</upper>
            <effort>1000</effort>
            <velocity>1</velocity>
          </limit>
          <dynamics>
            <damping>1</damping>
            <friction>0</friction>
            <spring_reference>0</spring_reference>
            <spring_stiffness>0</spring_stiffness>
          </dynamics>
          <use_parent_model_frame>1</use_parent_model_frame>
        </axis>
      </joint>
      <link name='COL_COL_COL_VIS_VIS_VIS_VIS_VIS_VIS_VIS_VIS_VIS_hollie_real.019'>
        <pose frame=''>-0.018368 -0.400963 2.05704 2.77323 -1.57079 1.99152</pose>
        <inertial>
          <pose frame=''>0 0 0 0 -0 0</pose>
          <mass>1e-05</mass>
          <inertia>
            <ixx>0.01</ixx>
            <ixy>0</ixy>
            <ixz>0</ixz>
            <iyy>0.01</iyy>
            <iyz>0</iyz>
            <izz>0.01</izz>
          </inertia>
        </inertial>
        <collision name='COL_COL_COL_VIS_VIS_VIS_VIS_VIS_VIS_VIS_VIS_VIS_hollie_real.019_collision'>
          <pose frame=''>-0 -0 -1e-06 0 -0 0</pose>
          <geometry>
            <mesh>
              <scale>1 1 1</scale>
              <uri>model://arm_robot/collisions/COL_COL_COL_VIS_VIS_VIS_VIS_VIS_VIS_VIS_VIS_VIS_hollie_real.019.dae</uri>
            </mesh>
          </geometry>
          <max_contacts>10</max_contacts>
          <surface>
            <contact>
              <ode/>
            </contact>
            <bounce/>
            <friction>
              <ode/>
            </friction>
          </surface>
        </collision>
        <visual name='COL_COL_COL_VIS_VIS_VIS_VIS_VIS_VIS_VIS_VIS_VIS_hollie_real.019_visual'>
          <pose frame=''>-0 -0 -1e-06 0 -0 0</pose>
          <geometry>
            <mesh>
              <scale>1 1 1</scale>
              <uri>model://arm_robot/meshes/VIS_COL_COL_VIS_VIS_VIS_VIS_VIS_VIS_VIS_VIS_VIS_hollie_real.019.dae</uri>
            </mesh>
          </geometry>
        </visual>
        <self_collide>0</self_collide>
        <kinematic>0</kinematic>
        <gravity>1</gravity>
      </link>
      <joint name='hollie_real_left_hand_j15' type='revolute'>
        <child>COL_COL_COL_VIS_VIS_VIS_VIS_VIS_VIS_VIS_VIS_VIS_hollie_real.019</child>
        <parent>COL_COL_COL_VIS_VIS_VIS_VIS_VIS_VIS_VIS_VIS_VIS_hollie_real.018</parent>
        <axis>
          <xyz>-0.052336 0.99863 0</xyz>
          <limit>
            <lower>0</lower>
            <upper>2.9141e+19</upper>
            <effort>1000</effort>
            <velocity>1</velocity>
          </limit>
          <dynamics>
            <damping>1</damping>
            <friction>0</friction>
            <spring_reference>0</spring_reference>
            <spring_stiffness>0</spring_stiffness>
          </dynamics>
          <use_parent_model_frame>1</use_parent_model_frame>
        </axis>
      </joint>
      <link name='COL_COL_COL_VIS_VIS_VIS_VIS_VIS_VIS_VIS_VIS_VIS_hollie_real.020'>
        <pose frame=''>-0.013339 -0.382274 1.9025 0 0 -1.51844</pose>
        <inertial>
          <pose frame=''>0 0 0 0 -0 0</pose>
          <mass>1e-05</mass>
          <inertia>
            <ixx>0.01</ixx>
            <ixy>0</ixy>
            <ixz>0</ixz>
            <iyy>0.01</iyy>
            <iyz>0</iyz>
            <izz>0.01</izz>
          </inertia>
        </inertial>
        <collision name='COL_COL_COL_VIS_VIS_VIS_VIS_VIS_VIS_VIS_VIS_VIS_hollie_real.020_collision'>
          <pose frame=''>0.0007 0 -0.010019 0 -0 0</pose>
          <geometry>
            <mesh>
              <scale>1 1 1</scale>
              <uri>model://arm_robot/collisions/COL_COL_COL_VIS_VIS_VIS_VIS_VIS_VIS_VIS_VIS_VIS_hollie_real.020.dae</uri>
            </mesh>
          </geometry>
          <max_contacts>10</max_contacts>
          <surface>
            <contact>
              <ode/>
            </contact>
            <bounce/>
            <friction>
              <ode/>
            </friction>
          </surface>
        </collision>
        <visual name='COL_COL_COL_VIS_VIS_VIS_VIS_VIS_VIS_VIS_VIS_VIS_hollie_real.020_visual'>
          <pose frame=''>0.0007 0 -0.010019 3.14159 -0 0</pose>
          <geometry>
            <mesh>
              <scale>1 1 1</scale>
              <uri>model://arm_robot/meshes/VIS_COL_COL_VIS_VIS_VIS_VIS_VIS_VIS_VIS_VIS_VIS_hollie_real.020.dae</uri>
            </mesh>
          </geometry>
        </visual>
        <self_collide>0</self_collide>
        <kinematic>0</kinematic>
        <gravity>1</gravity>
      </link>
      <joint name='hollie_real_left_hand_j5' type='revolute'>
        <child>COL_COL_COL_VIS_VIS_VIS_VIS_VIS_VIS_VIS_VIS_VIS_hollie_real.020</child>
        <parent>COL_COL_COL_VIS_VIS_VIS_VIS_VIS_VIS_VIS_VIS_VIS_hollie_real.007</parent>
        <axis>
          <xyz>0 0 1</xyz>
          <limit>
            <lower>0</lower>
            <upper>2.15796e+19</upper>
            <effort>1000</effort>
            <velocity>1</velocity>
          </limit>
          <dynamics>
            <damping>1</damping>
            <friction>0</friction>
            <spring_reference>0</spring_reference>
            <spring_stiffness>0</spring_stiffness>
          </dynamics>
          <use_parent_model_frame>1</use_parent_model_frame>
        </axis>
      </joint>
      <link name='hollie_real_left_hand_f5_link'>
        <pose frame=''>-0.019331 -0.382588 1.9025 0 0 -1.51844</pose>
        <inertial>
          <pose frame=''>0 0 0 0 -0 0</pose>
          <mass>1e-05</mass>
          <inertia>
            <ixx>0.01</ixx>
            <ixy>0</ixy>
            <ixz>0</ixz>
            <iyy>0.01</iyy>
            <iyz>0</iyz>
            <izz>0.01</izz>
          </inertia>
        </inertial>
        <self_collide>0</self_collide>
        <kinematic>0</kinematic>
        <gravity>1</gravity>
      </link>
      <joint name='hollie_real_left_hand_f5' type='prismatic'>
        <child>hollie_real_left_hand_f5_link</child>
        <parent>COL_COL_COL_VIS_VIS_VIS_VIS_VIS_VIS_VIS_VIS_VIS_hollie_real.020</parent>
        <axis>
          <xyz>0.052336 -0.99863 -0</xyz>
          <limit>
            <lower>0</lower>
            <upper>0</upper>
            <effort>1000</effort>
            <velocity>1</velocity>
          </limit>
          <dynamics>
            <damping>1</damping>
            <friction>0</friction>
            <spring_reference>0</spring_reference>
            <spring_stiffness>0</spring_stiffness>
          </dynamics>
          <use_parent_model_frame>1</use_parent_model_frame>
        </axis>
      </joint>
      <link name='hollie_real_left_hand_f6_link'>
        <pose frame=''>-0.019331 -0.382588 1.9025 0 0 -1.51844</pose>
        <inertial>
          <pose frame=''>0 0 0 0 -0 0</pose>
          <mass>1e-05</mass>
          <inertia>
            <ixx>0.01</ixx>
            <ixy>0</ixy>
            <ixz>0</ixz>
            <iyy>0.01</iyy>
            <iyz>0</iyz>
            <izz>0.01</izz>
          </inertia>
        </inertial>
        <self_collide>0</self_collide>
        <kinematic>0</kinematic>
        <gravity>1</gravity>
      </link>
      <joint name='hollie_real_left_hand_f6' type='prismatic'>
        <child>hollie_real_left_hand_f6_link</child>
        <parent>hollie_real_left_hand_f5_link</parent>
        <axis>
          <xyz>0.052336 -0.99863 -0</xyz>
          <limit>
            <lower>0</lower>
            <upper>0</upper>
            <effort>1000</effort>
            <velocity>1</velocity>
          </limit>
          <dynamics>
            <damping>1</damping>
            <friction>0</friction>
            <spring_reference>0</spring_reference>
            <spring_stiffness>0</spring_stiffness>
          </dynamics>
          <use_parent_model_frame>1</use_parent_model_frame>
        </axis>
      </joint>
      <link name='hollie_real_left_hand_f7_link'>
        <pose frame=''>-0.019331 -0.382588 1.9025 0 0 -1.51844</pose>
        <inertial>
          <pose frame=''>0 0 0 0 -0 0</pose>
          <mass>1e-05</mass>
          <inertia>
            <ixx>0.01</ixx>
            <ixy>0</ixy>
            <ixz>0</ixz>
            <iyy>0.01</iyy>
            <iyz>0</iyz>
            <izz>0.01</izz>
          </inertia>
        </inertial>
        <self_collide>0</self_collide>
        <kinematic>0</kinematic>
        <gravity>1</gravity>
      </link>
      <joint name='hollie_real_left_hand_f7' type='prismatic'>
        <child>hollie_real_left_hand_f7_link</child>
        <parent>hollie_real_left_hand_f6_link</parent>
        <axis>
          <xyz>0.052336 -0.99863 -0</xyz>
          <limit>
            <lower>0</lower>
            <upper>0</upper>
            <effort>1000</effort>
            <velocity>1</velocity>
          </limit>
          <dynamics>
            <damping>1</damping>
            <friction>0</friction>
            <spring_reference>0</spring_reference>
            <spring_stiffness>0</spring_stiffness>
          </dynamics>
          <use_parent_model_frame>1</use_parent_model_frame>
        </axis>
      </joint>
      <link name='COL_COL_COL_VIS_VIS_VIS_VIS_VIS_VIS_VIS_VIS_VIS_hollie_real.021'>
        <pose frame=''>-0.020658 -0.357268 1.9585 1.20243 -1.57079 1.99152</pose>
        <inertial>
          <pose frame=''>0 0 0 0 -0 0</pose>
          <mass>1e-05</mass>
          <inertia>
            <ixx>0.01</ixx>
            <ixy>0</ixy>
            <ixz>0</ixz>
            <iyy>0.01</iyy>
            <iyz>0</iyz>
            <izz>0.01</izz>
          </inertia>
        </inertial>
        <collision name='COL_COL_COL_VIS_VIS_VIS_VIS_VIS_VIS_VIS_VIS_VIS_hollie_real.021_collision'>
          <pose frame=''>-1e-06 -2e-06 -0.01321 0 -0 0</pose>
          <geometry>
            <mesh>
              <scale>1 1 1</scale>
              <uri>model://arm_robot/collisions/COL_COL_COL_VIS_VIS_VIS_VIS_VIS_VIS_VIS_VIS_VIS_hollie_real.021.dae</uri>
            </mesh>
          </geometry>
          <max_contacts>10</max_contacts>
          <surface>
            <contact>
              <ode/>
            </contact>
            <bounce/>
            <friction>
              <ode/>
            </friction>
          </surface>
        </collision>
        <visual name='COL_COL_COL_VIS_VIS_VIS_VIS_VIS_VIS_VIS_VIS_VIS_hollie_real.021_visual'>
          <pose frame=''>-1e-06 -2e-06 -0.01321 0.387539 -1e-06 -2e-06</pose>
          <geometry>
            <mesh>
              <scale>1 1 1</scale>
              <uri>model://arm_robot/meshes/VIS_COL_COL_VIS_VIS_VIS_VIS_VIS_VIS_VIS_VIS_VIS_hollie_real.021.dae</uri>
            </mesh>
          </geometry>
        </visual>
        <self_collide>0</self_collide>
        <kinematic>0</kinematic>
        <gravity>1</gravity>
      </link>
      <joint name='hollie_real_left_hand_Finger_Spread' type='revolute'>
        <child>COL_COL_COL_VIS_VIS_VIS_VIS_VIS_VIS_VIS_VIS_VIS_hollie_real.021</child>
        <parent>hollie_real_left_hand_f7_link</parent>
        <axis>
          <xyz>0.99863 0.052336 0</xyz>
          <limit>
            <lower>0</lower>
            <upper>1.27334e+19</upper>
            <effort>1000</effort>
            <velocity>1</velocity>
          </limit>
          <dynamics>
            <damping>1</damping>
            <friction>0</friction>
            <spring_reference>0</spring_reference>
            <spring_stiffness>0</spring_stiffness>
          </dynamics>
          <use_parent_model_frame>1</use_parent_model_frame>
        </axis>
      </joint>
      <link name='COL_COL_COL_VIS_VIS_VIS_VIS_VIS_VIS_VIS_VIS_VIS_hollie_real.022'>
        <pose frame=''>-0.020658 -0.357268 1.9585 2.77323 -1.57079 1.99152</pose>
        <inertial>
          <pose frame=''>0 0 0 0 -0 0</pose>
          <mass>1e-05</mass>
          <inertia>
            <ixx>0.01</ixx>
            <ixy>0</ixy>
            <ixz>0</ixz>
            <iyy>0.01</iyy>
            <iyz>0</iyz>
            <izz>0.01</izz>
          </inertia>
        </inertial>
        <collision name='COL_COL_COL_VIS_VIS_VIS_VIS_VIS_VIS_VIS_VIS_VIS_hollie_real.022_collision'>
          <pose frame=''>1e-06 0 0 0 -0 0</pose>
          <geometry>
            <mesh>
              <scale>1 1 1</scale>
              <uri>model://arm_robot/collisions/COL_COL_COL_VIS_VIS_VIS_VIS_VIS_VIS_VIS_VIS_VIS_hollie_real.022.dae</uri>
            </mesh>
          </geometry>
          <max_contacts>10</max_contacts>
          <surface>
            <contact>
              <ode/>
            </contact>
            <bounce/>
            <friction>
              <ode/>
            </friction>
          </surface>
        </collision>
        <visual name='COL_COL_COL_VIS_VIS_VIS_VIS_VIS_VIS_VIS_VIS_VIS_hollie_real.022_visual'>
          <pose frame=''>1e-06 0 0 0 -0 0</pose>
          <geometry>
            <mesh>
              <scale>1 1 1</scale>
              <uri>model://arm_robot/meshes/VIS_COL_COL_VIS_VIS_VIS_VIS_VIS_VIS_VIS_VIS_VIS_hollie_real.022.dae</uri>
            </mesh>
          </geometry>
        </visual>
        <self_collide>0</self_collide>
        <kinematic>0</kinematic>
        <gravity>1</gravity>
      </link>
      <joint name='hollie_real_left_hand_Pinky' type='revolute'>
        <child>COL_COL_COL_VIS_VIS_VIS_VIS_VIS_VIS_VIS_VIS_VIS_hollie_real.022</child>
        <parent>COL_COL_COL_VIS_VIS_VIS_VIS_VIS_VIS_VIS_VIS_VIS_hollie_real.021</parent>
        <axis>
          <xyz>-0.052336 0.99863 0</xyz>
          <limit>
            <lower>0</lower>
            <upper>2.14462e+19</upper>
            <effort>1000</effort>
            <velocity>1</velocity>
          </limit>
          <dynamics>
            <damping>1</damping>
            <friction>0</friction>
            <spring_reference>0</spring_reference>
            <spring_stiffness>0</spring_stiffness>
          </dynamics>
          <use_parent_model_frame>1</use_parent_model_frame>
        </axis>
      </joint>
      <link name='COL_COL_COL_VIS_VIS_VIS_VIS_VIS_VIS_VIS_VIS_VIS_hollie_real.023'>
        <pose frame=''>-0.020658 -0.357268 2.00304 2.77323 -1.57079 1.99152</pose>
        <inertial>
          <pose frame=''>0 0 0 0 -0 0</pose>
          <mass>1e-05</mass>
          <inertia>
            <ixx>0.01</ixx>
            <ixy>0</ixy>
            <ixz>0</ixz>
            <iyy>0.01</iyy>
            <iyz>0</iyz>
            <izz>0.01</izz>
          </inertia>
        </inertial>
        <collision name='COL_COL_COL_VIS_VIS_VIS_VIS_VIS_VIS_VIS_VIS_VIS_hollie_real.023_collision'>
          <pose frame=''>-1e-06 1e-06 0 0 -0 0</pose>
          <geometry>
            <mesh>
              <scale>1 1 1</scale>
              <uri>model://arm_robot/collisions/COL_COL_COL_VIS_VIS_VIS_VIS_VIS_VIS_VIS_VIS_VIS_hollie_real.023.dae</uri>
            </mesh>
          </geometry>
          <max_contacts>10</max_contacts>
          <surface>
            <contact>
              <ode/>
            </contact>
            <bounce/>
            <friction>
              <ode/>
            </friction>
          </surface>
        </collision>
        <visual name='COL_COL_COL_VIS_VIS_VIS_VIS_VIS_VIS_VIS_VIS_VIS_hollie_real.023_visual'>
          <pose frame=''>-1e-06 1e-06 0 0 0 -1e-06</pose>
          <geometry>
            <mesh>
              <scale>1 1 1</scale>
              <uri>model://arm_robot/meshes/VIS_COL_COL_VIS_VIS_VIS_VIS_VIS_VIS_VIS_VIS_VIS_hollie_real.023.dae</uri>
            </mesh>
          </geometry>
        </visual>
        <self_collide>0</self_collide>
        <kinematic>0</kinematic>
        <gravity>1</gravity>
      </link>
      <joint name='hollie_real_left_hand_j13' type='revolute'>
        <child>COL_COL_COL_VIS_VIS_VIS_VIS_VIS_VIS_VIS_VIS_VIS_hollie_real.023</child>
        <parent>COL_COL_COL_VIS_VIS_VIS_VIS_VIS_VIS_VIS_VIS_VIS_hollie_real.022</parent>
        <axis>
          <xyz>-0.052336 0.99863 0</xyz>
          <limit>
            <lower>0</lower>
            <upper>2.9141e+19</upper>
            <effort>1000</effort>
            <velocity>1</velocity>
          </limit>
          <dynamics>
            <damping>1</damping>
            <friction>0</friction>
            <spring_reference>0</spring_reference>
            <spring_stiffness>0</spring_stiffness>
          </dynamics>
          <use_parent_model_frame>1</use_parent_model_frame>
        </axis>
      </joint>
      <link name='COL_COL_COL_VIS_VIS_VIS_VIS_VIS_VIS_VIS_VIS_VIS_hollie_real.024'>
        <pose frame=''>-0.020658 -0.357268 2.02504 2.77323 -1.57079 1.99152</pose>
        <inertial>
          <pose frame=''>0 0 0 0 -0 0</pose>
          <mass>1e-05</mass>
          <inertia>
            <ixx>0.01</ixx>
            <ixy>0</ixy>
            <ixz>0</ixz>
            <iyy>0.01</iyy>
            <iyz>0</iyz>
            <izz>0.01</izz>
          </inertia>
        </inertial>
        <collision name='COL_COL_COL_VIS_VIS_VIS_VIS_VIS_VIS_VIS_VIS_VIS_hollie_real.024_collision'>
          <pose frame=''>-1e-06 -1e-06 1e-06 0 -0 0</pose>
          <geometry>
            <mesh>
              <scale>1 1 1</scale>
              <uri>model://arm_robot/collisions/COL_COL_COL_VIS_VIS_VIS_VIS_VIS_VIS_VIS_VIS_VIS_hollie_real.024.dae</uri>
            </mesh>
          </geometry>
          <max_contacts>10</max_contacts>
          <surface>
            <contact>
              <ode/>
            </contact>
            <bounce/>
            <friction>
              <ode/>
            </friction>
          </surface>
        </collision>
        <visual name='COL_COL_COL_VIS_VIS_VIS_VIS_VIS_VIS_VIS_VIS_VIS_hollie_real.024_visual'>
          <pose frame=''>-1e-06 -1e-06 1e-06 0 -0 0</pose>
          <geometry>
            <mesh>
              <scale>1 1 1</scale>
              <uri>model://arm_robot/meshes/VIS_COL_COL_VIS_VIS_VIS_VIS_VIS_VIS_VIS_VIS_VIS_hollie_real.024.dae</uri>
            </mesh>
          </geometry>
        </visual>
        <self_collide>0</self_collide>
        <kinematic>0</kinematic>
        <gravity>1</gravity>
      </link>
      <joint name='hollie_real_left_hand_j17' type='revolute'>
        <child>COL_COL_COL_VIS_VIS_VIS_VIS_VIS_VIS_VIS_VIS_VIS_hollie_real.024</child>
        <parent>COL_COL_COL_VIS_VIS_VIS_VIS_VIS_VIS_VIS_VIS_VIS_hollie_real.023</parent>
        <axis>
          <xyz>-0.052336 0.99863 0</xyz>
          <limit>
            <lower>0</lower>
            <upper>3.05194e+19</upper>
            <effort>1000</effort>
            <velocity>1</velocity>
          </limit>
          <dynamics>
            <damping>1</damping>
            <friction>0</friction>
            <spring_reference>0</spring_reference>
            <spring_stiffness>0</spring_stiffness>
          </dynamics>
          <use_parent_model_frame>1</use_parent_model_frame>
        </axis>
      </joint>
      <link name='hollie_real_left_hand_f8_link'>
        <pose frame=''>-0.019331 -0.382588 1.9025 0 0 -1.51844</pose>
        <inertial>
          <pose frame=''>0 0 0 0 -0 0</pose>
          <mass>1e-05</mass>
          <inertia>
            <ixx>0.01</ixx>
            <ixy>0</ixy>
            <ixz>0</ixz>
            <iyy>0.01</iyy>
            <iyz>0</iyz>
            <izz>0.01</izz>
          </inertia>
        </inertial>
        <self_collide>0</self_collide>
        <kinematic>0</kinematic>
        <gravity>1</gravity>
      </link>
      <joint name='hollie_real_left_hand_f8' type='prismatic'>
        <child>hollie_real_left_hand_f8_link</child>
        <parent>hollie_real_left_hand_f6_link</parent>
        <axis>
          <xyz>0.052336 -0.99863 -0</xyz>
          <limit>
            <lower>0</lower>
            <upper>0</upper>
            <effort>1000</effort>
            <velocity>1</velocity>
          </limit>
          <dynamics>
            <damping>1</damping>
            <friction>0</friction>
            <spring_reference>0</spring_reference>
            <spring_stiffness>0</spring_stiffness>
          </dynamics>
          <use_parent_model_frame>1</use_parent_model_frame>
        </axis>
      </joint>
      <link name='COL_COL_COL_VIS_VIS_VIS_VIS_VIS_VIS_VIS_VIS_VIS_hollie_real.025'>
        <pose frame=''>-0.019533 -0.378738 1.968 1.20243 -1.57079 1.99152</pose>
        <inertial>
          <pose frame=''>0 0 0 0 -0 0</pose>
          <mass>1e-05</mass>
          <inertia>
            <ixx>0.01</ixx>
            <ixy>0</ixy>
            <ixz>0</ixz>
            <iyy>0.01</iyy>
            <iyz>0</iyz>
            <izz>0.01</izz>
          </inertia>
        </inertial>
        <collision name='COL_COL_COL_VIS_VIS_VIS_VIS_VIS_VIS_VIS_VIS_VIS_hollie_real.025_collision'>
          <pose frame=''>-0 -1e-06 -0.01321 0 -0 0</pose>
          <geometry>
            <mesh>
              <scale>1 1 1</scale>
              <uri>model://arm_robot/collisions/COL_COL_COL_VIS_VIS_VIS_VIS_VIS_VIS_VIS_VIS_VIS_hollie_real.025.dae</uri>
            </mesh>
          </geometry>
          <max_contacts>10</max_contacts>
          <surface>
            <contact>
              <ode/>
            </contact>
            <bounce/>
            <friction>
              <ode/>
            </friction>
          </surface>
        </collision>
        <visual name='COL_COL_COL_VIS_VIS_VIS_VIS_VIS_VIS_VIS_VIS_VIS_hollie_real.025_visual'>
          <pose frame=''>-0 -1e-06 -0.01321 0.191341 -1e-06 0</pose>
          <geometry>
            <mesh>
              <scale>1 1 1</scale>
              <uri>model://arm_robot/meshes/VIS_COL_COL_VIS_VIS_VIS_VIS_VIS_VIS_VIS_VIS_VIS_hollie_real.025.dae</uri>
            </mesh>
          </geometry>
        </visual>
        <self_collide>0</self_collide>
        <kinematic>0</kinematic>
        <gravity>1</gravity>
      </link>
      <joint name='hollie_real_left_hand_ring_spread' type='revolute'>
        <child>COL_COL_COL_VIS_VIS_VIS_VIS_VIS_VIS_VIS_VIS_VIS_hollie_real.025</child>
        <parent>hollie_real_left_hand_f8_link</parent>
        <axis>
          <xyz>0.99863 0.052336 0</xyz>
          <limit>
            <lower>0</lower>
            <upper>6.29852e+18</upper>
            <effort>1000</effort>
            <velocity>1</velocity>
          </limit>
          <dynamics>
            <damping>1</damping>
            <friction>0</friction>
            <spring_reference>0</spring_reference>
            <spring_stiffness>0</spring_stiffness>
          </dynamics>
          <use_parent_model_frame>1</use_parent_model_frame>
        </axis>
      </joint>
      <link name='COL_COL_COL_VIS_VIS_VIS_VIS_VIS_VIS_VIS_VIS_VIS_hollie_real.026'>
        <pose frame=''>-0.019533 -0.378738 1.968 2.77323 -1.57079 1.99152</pose>
        <inertial>
          <pose frame=''>0 0 0 0 -0 0</pose>
          <mass>1e-05</mass>
          <inertia>
            <ixx>0.01</ixx>
            <ixy>0</ixy>
            <ixz>0</ixz>
            <iyy>0.01</iyy>
            <iyz>0</iyz>
            <izz>0.01</izz>
          </inertia>
        </inertial>
        <collision name='COL_COL_COL_VIS_VIS_VIS_VIS_VIS_VIS_VIS_VIS_VIS_hollie_real.026_collision'>
          <pose frame=''>-1e-06 0 -1e-06 0 -0 0</pose>
          <geometry>
            <mesh>
              <scale>1 1 1</scale>
              <uri>model://arm_robot/collisions/COL_COL_COL_VIS_VIS_VIS_VIS_VIS_VIS_VIS_VIS_VIS_hollie_real.026.dae</uri>
            </mesh>
          </geometry>
          <max_contacts>10</max_contacts>
          <surface>
            <contact>
              <ode/>
            </contact>
            <bounce/>
            <friction>
              <ode/>
            </friction>
          </surface>
        </collision>
        <visual name='COL_COL_COL_VIS_VIS_VIS_VIS_VIS_VIS_VIS_VIS_VIS_hollie_real.026_visual'>
          <pose frame=''>-1e-06 0 -1e-06 -0.052607 -0 -1e-06</pose>
          <geometry>
            <mesh>
              <scale>1 1 1</scale>
              <uri>model://arm_robot/meshes/VIS_COL_COL_VIS_VIS_VIS_VIS_VIS_VIS_VIS_VIS_VIS_hollie_real.026.dae</uri>
            </mesh>
          </geometry>
        </visual>
        <self_collide>0</self_collide>
        <kinematic>0</kinematic>
        <gravity>1</gravity>
      </link>
      <joint name='hollie_real_left_hand_Ring_Finger' type='revolute'>
        <child>COL_COL_COL_VIS_VIS_VIS_VIS_VIS_VIS_VIS_VIS_VIS_hollie_real.026</child>
        <parent>COL_COL_COL_VIS_VIS_VIS_VIS_VIS_VIS_VIS_VIS_VIS_hollie_real.025</parent>
        <axis>
          <xyz>-0.052336 0.99863 0</xyz>
          <limit>
            <lower>0</lower>
            <upper>2.14462e+19</upper>
            <effort>1000</effort>
            <velocity>1</velocity>
          </limit>
          <dynamics>
            <damping>1</damping>
            <friction>0</friction>
            <spring_reference>0</spring_reference>
            <spring_stiffness>0</spring_stiffness>
          </dynamics>
          <use_parent_model_frame>1</use_parent_model_frame>
        </axis>
      </joint>
      <link name='COL_COL_COL_VIS_VIS_VIS_VIS_VIS_VIS_VIS_VIS_VIS_hollie_real.027'>
        <pose frame=''>-0.019533 -0.378738 2.01804 2.77323 -1.57079 1.99152</pose>
        <inertial>
          <pose frame=''>0 0 0 0 -0 0</pose>
          <mass>1e-05</mass>
          <inertia>
            <ixx>0.01</ixx>
            <ixy>0</ixy>
            <ixz>0</ixz>
            <iyy>0.01</iyy>
            <iyz>0</iyz>
            <izz>0.01</izz>
          </inertia>
        </inertial>
        <collision name='COL_COL_COL_VIS_VIS_VIS_VIS_VIS_VIS_VIS_VIS_VIS_hollie_real.027_collision'>
          <pose frame=''>-0 0 -0 0 -0 0</pose>
          <geometry>
            <mesh>
              <scale>1 1 1</scale>
              <uri>model://arm_robot/collisions/COL_COL_COL_VIS_VIS_VIS_VIS_VIS_VIS_VIS_VIS_VIS_hollie_real.027.dae</uri>
            </mesh>
          </geometry>
          <max_contacts>10</max_contacts>
          <surface>
            <contact>
              <ode/>
            </contact>
            <bounce/>
            <friction>
              <ode/>
            </friction>
          </surface>
        </collision>
        <visual name='COL_COL_COL_VIS_VIS_VIS_VIS_VIS_VIS_VIS_VIS_VIS_hollie_real.027_visual'>
          <pose frame=''>-0 0 -0 0 -0 0</pose>
          <geometry>
            <mesh>
              <scale>1 1 1</scale>
              <uri>model://arm_robot/meshes/VIS_COL_COL_VIS_VIS_VIS_VIS_VIS_VIS_VIS_VIS_VIS_hollie_real.027.dae</uri>
            </mesh>
          </geometry>
        </visual>
        <self_collide>0</self_collide>
        <kinematic>0</kinematic>
        <gravity>1</gravity>
      </link>
      <joint name='hollie_real_left_hand_j12' type='revolute'>
        <child>COL_COL_COL_VIS_VIS_VIS_VIS_VIS_VIS_VIS_VIS_VIS_hollie_real.027</child>
        <parent>COL_COL_COL_VIS_VIS_VIS_VIS_VIS_VIS_VIS_VIS_VIS_hollie_real.026</parent>
        <axis>
          <xyz>-0.052336 0.99863 0</xyz>
          <limit>
            <lower>0</lower>
            <upper>2.9141e+19</upper>
            <effort>1000</effort>
            <velocity>1</velocity>
          </limit>
          <dynamics>
            <damping>1</damping>
            <friction>0</friction>
            <spring_reference>0</spring_reference>
            <spring_stiffness>0</spring_stiffness>
          </dynamics>
          <use_parent_model_frame>1</use_parent_model_frame>
        </axis>
      </joint>
      <link name='COL_COL_COL_VIS_VIS_VIS_VIS_VIS_VIS_VIS_VIS_VIS_hollie_real_lef'>
        <pose frame=''>-0.019533 -0.378738 2.05004 2.77323 -1.57079 1.99152</pose>
        <inertial>
          <pose frame=''>0 0 0 0 -0 0</pose>
          <mass>1e-05</mass>
          <inertia>
            <ixx>0.01</ixx>
            <ixy>0</ixy>
            <ixz>0</ixz>
            <iyy>0.01</iyy>
            <iyz>0</iyz>
            <izz>0.01</izz>
          </inertia>
        </inertial>
        <collision name='COL_COL_COL_VIS_VIS_VIS_VIS_VIS_VIS_VIS_VIS_VIS_hollie_real_lef_collision'>
          <pose frame=''>1e-06 -0 -0 0 -0 0</pose>
          <geometry>
            <mesh>
              <scale>1 1 1</scale>
              <uri>model://arm_robot/collisions/COL_COL_COL_VIS_VIS_VIS_VIS_VIS_VIS_VIS_VIS_VIS_hollie_real_lef.dae</uri>
            </mesh>
          </geometry>
          <max_contacts>10</max_contacts>
          <surface>
            <contact>
              <ode/>
            </contact>
            <bounce/>
            <friction>
              <ode/>
            </friction>
          </surface>
        </collision>
        <visual name='COL_COL_COL_VIS_VIS_VIS_VIS_VIS_VIS_VIS_VIS_VIS_hollie_real_lef_visual'>
          <pose frame=''>1e-06 -0 -0 0.020018 -0 0</pose>
          <geometry>
            <mesh>
              <scale>1 1 1</scale>
              <uri>model://arm_robot/meshes/VIS_COL_COL_VIS_VIS_VIS_VIS_VIS_VIS_VIS_VIS_VIS_hollie_real_lef.dae</uri>
            </mesh>
          </geometry>
        </visual>
        <self_collide>0</self_collide>
        <kinematic>0</kinematic>
        <gravity>1</gravity>
      </link>
      <joint name='hollie_real_left_hand_j16' type='revolute'>
        <child>COL_COL_COL_VIS_VIS_VIS_VIS_VIS_VIS_VIS_VIS_VIS_hollie_real_lef</child>
        <parent>COL_COL_COL_VIS_VIS_VIS_VIS_VIS_VIS_VIS_VIS_VIS_hollie_real.027</parent>
        <axis>
          <xyz>-0.052336 0.99863 0</xyz>
          <limit>
            <lower>0</lower>
            <upper>3.04736e+19</upper>
            <effort>1000</effort>
            <velocity>1</velocity>
          </limit>
          <dynamics>
            <damping>1</damping>
            <friction>0</friction>
            <spring_reference>0</spring_reference>
            <spring_stiffness>0</spring_stiffness>
          </dynamics>
          <use_parent_model_frame>1</use_parent_model_frame>
        </axis>
      </joint>
      <static>0</static>
      <plugin name='generic_controller' filename='libgeneric_controller_plugin.so'>
        <controller joint_name='hollie_real_base_x_joint'>
          <type>position</type>
          <pid>500.0 10.0 50.0</pid>
        </controller>
        <controller joint_name='hollie_real_left_arm_0_joint'>
          <type>position</type>
          <pid>500.0 10.0 50.0</pid>
        </controller>
        <controller joint_name='hollie_real_left_arm_1_joint'>
          <type>position</type>
          <pid>500.0 10.0 50.0</pid>
        </controller>
        <controller joint_name='hollie_real_left_arm_2_joint'>
          <type>position</type>
          <pid>500.0 10.0 50.0</pid>
        </controller>
        <controller joint_name='hollie_real_left_arm_3_joint'>
          <type>position</type>
          <pid>500.0 10.0 50.0</pid>
        </controller>
        <controller joint_name='hollie_real_left_arm_4_joint'>
          <type>position</type>
          <pid>500.0 10.0 50.0</pid>
        </controller>
        <controller joint_name='hollie_real_left_arm_5_joint'>
          <type>position</type>
          <pid>500.0 10.0 50.0</pid>
        </controller>
        <controller joint_name='hollie_real_left_arm_6_joint'>
          <type>position</type>
          <pid>500.0 10.0 50.0</pid>
        </controller>
        <controller joint_name='hollie_real_left_hand_base_joint'>
          <type>position</type>
          <pid>100.0 0.1 0.1</pid>
        </controller>
        <controller joint_name='hollie_real_left_hand_f4'>
          <type>position</type>
          <pid>100.0 0.1 0.1</pid>
        </controller>
        <controller joint_name='hollie_real_left_hand_Thumb_Opposition'>
          <type>position</type>
          <pid>100.0 0.1 0.1</pid>
        </controller>
        <controller joint_name='hollie_real_left_hand_Thumb_Helper'>
          <type>position</type>
          <pid>100.0 0.1 0.1</pid>
        </controller>
        <controller joint_name='hollie_real_left_hand_Thumb_Flexion'>
          <type>position</type>
          <pid>100.0 0.1 0.1</pid>
        </controller>
        <controller joint_name='hollie_real_left_hand_j3'>
          <type>position</type>
          <pid>100.0 0.1 0.1</pid>
        </controller>
        <controller joint_name='hollie_real_left_hand_j4'>
          <type>position</type>
          <pid>100.0 0.1 0.1</pid>
        </controller>
        <controller joint_name='hollie_real_left_hand_f1'>
          <type>position</type>
          <pid>100.0 0.1 0.1</pid>
        </controller>
        <controller joint_name='hollie_real_left_hand_f2'>
          <type>position</type>
          <pid>100.0 0.1 0.1</pid>
        </controller>
        <controller joint_name='hollie_real_left_hand_f3'>
          <type>position</type>
          <pid>100.0 0.1 0.1</pid>
        </controller>
        <controller joint_name='hollie_real_left_hand_index_spread'>
          <type>position</type>
          <pid>100.0 0.1 0.1</pid>
        </controller>
        <controller joint_name='hollie_real_left_hand_Index_Finger_Proximal'>
          <type>position</type>
          <pid>100.0 0.1 0.1</pid>
        </controller>
        <controller joint_name='hollie_real_left_hand_Index_Finger_Distal'>
          <type>position</type>
          <pid>100.0 0.1 0.1</pid>
        </controller>
        <controller joint_name='hollie_real_left_hand_j14'>
          <type>position</type>
          <pid>100.0 0.1 0.1</pid>
        </controller>
        <controller joint_name='hollie_real_left_hand_middle_spread_dummy'>
          <type>position</type>
          <pid>100.0 0.1 0.1</pid>
        </controller>
        <controller joint_name='hollie_real_left_hand_Middle_Finger_Proximal'>
          <type>position</type>
          <pid>100.0 0.1 0.1</pid>
        </controller>
        <controller joint_name='hollie_real_left_hand_Middle_Finger_Distal'>
          <type>position</type>
          <pid>100.0 0.1 0.1</pid>
        </controller>
        <controller joint_name='hollie_real_left_hand_j15'>
          <type>position</type>
          <pid>100.0 0.1 0.1</pid>
        </controller>
        <controller joint_name='hollie_real_left_hand_j5'>
          <type>position</type>
          <pid>100.0 0.1 0.1</pid>
        </controller>
        <controller joint_name='hollie_real_left_hand_f5'>
          <type>position</type>
          <pid>100.0 0.1 0.1</pid>
        </controller>
        <controller joint_name='hollie_real_left_hand_f6'>
          <type>position</type>
          <pid>100.0 0.1 0.1</pid>
        </controller>
        <controller joint_name='hollie_real_left_hand_f7'>
          <type>position</type>
          <pid>100.0 0.1 0.1</pid>
        </controller>
        <controller joint_name='hollie_real_left_hand_Finger_Spread'>
          <type>position</type>
          <pid>100.0 0.1 0.1</pid>
        </controller>
        <controller joint_name='hollie_real_left_hand_Pinky'>
          <type>position</type>
          <pid>100.0 0.1 0.1</pid>
        </controller>
        <controller joint_name='hollie_real_left_hand_j13'>
          <type>position</type>
          <pid>100.0 0.1 0.1</pid>
        </controller>
        <controller joint_name='hollie_real_left_hand_j17'>
          <type>position</type>
          <pid>100.0 0.1 0.1</pid>
        </controller>
        <controller joint_name='hollie_real_left_hand_f8'>
          <type>position</type>
          <pid>100.0 0.1 0.1</pid>
        </controller>
        <controller joint_name='hollie_real_left_hand_ring_spread'>
          <type>position</type>
          <pid>100.0 0.1 0.1</pid>
        </controller>
        <controller joint_name='hollie_real_left_hand_Ring_Finger'>
          <type>position</type>
          <pid>100.0 0.1 0.1</pid>
        </controller>
        <controller joint_name='hollie_real_left_hand_j12'>
          <type>position</type>
          <pid>100.0 0.1 0.1</pid>
        </controller>
        <controller joint_name='hollie_real_left_hand_j16'>
          <type>position</type>
          <pid>100.0 0.1 0.1</pid>
        </controller>
      </plugin>
    </model>
    <state world_name='default'>
      <sim_time>924 383000000</sim_time>
      <real_time>218 934933707</real_time>
      <wall_time>1498218287 255295562</wall_time>
      <iterations>194031</iterations>
      <model name='HoLLiE'>
        <pose frame=''>1.00272 1.57632 0.019497 -0.00057 0.000577 3.10616</pose>
        <link name='COL_COL_COL_VIS_VIS_VIS_VIS_VIS_VIS_VIS_VIS_VIS_hollie_real.000'>
          <pose frame=''>1.01621 1.97545 1.12973 0.00064 0.000514 -1.55974</pose>
          <velocity>0.016071 -0.002597 -0.005133 0.012338 0.017451 0.973891</velocity>
          <acceleration>38.3857 -6.02305 -0.935729 -3.01144 -0.508108 2.66225</acceleration>
          <wrench>11.2716 -1.76861 -0.274768 0 -0 0</wrench>
        </link>
        <link name='COL_COL_COL_VIS_VIS_VIS_VIS_VIS_VIS_VIS_VIS_VIS_hollie_real.001'>
          <pose frame=''>1.01621 1.97545 1.12972 1.57144 0.000992 -1.55974</pose>
          <velocity>0.015144 -0.002848 -0.004519 0.01366 0.026938 0.973896</velocity>
          <acceleration>36.5068 -6.95934 0.990369 2.27624 0.322298 2.66136</acceleration>
          <wrench>61.445 -11.7133 1.6669 0 -0 0</wrench>
        </link>
        <link name='COL_COL_COL_VIS_VIS_VIS_VIS_VIS_VIS_VIS_VIS_VIS_hollie_real.002'>
          <pose frame=''>1.01599 1.9751 1.47972 1.57016 -0.001471 1.58185</pose>
          <velocity>0.01987 -0.0051 -0.00441 0.134656 0.030446 0.973973</velocity>
          <acceleration>43.1022 -10.4398 1.31673 -0.586542 0.750473 -0.32814</acceleration>
          <wrench>90.5145 -21.9236 2.76514 0 -0 0</wrench>
        </link>
        <link name='COL_COL_COL_VIS_VIS_VIS_VIS_VIS_VIS_VIS_VIS_VIS_hollie_real.003'>
          <pose frame=''>1.01595 1.97515 1.47972 0.001352 0.000856 -0.957133</pose>
          <velocity>0.017949 -0.00288 -0.004342 0.117079 -0.006895 -1.31648</velocity>
          <acceleration>39.3094 -6.06448 1.52102 -0.929721 1.36976 0.862217</acceleration>
          <wrench>66.162 -10.2072 2.56004 0 -0 0</wrench>
        </link>
        <link name='COL_COL_COL_VIS_VIS_VIS_VIS_VIS_VIS_VIS_VIS_VIS_hollie_real.004'>
          <pose frame=''>1.02007 1.97773 1.78473 1.56945 -0.000701 2.18445</pose>
          <velocity>-0.02905 0.033154 -0.003916 0.09585 -0.018573 -1.31651</velocity>
          <acceleration>-55.5521 63.9415 2.4258 0.874507 -1.36688 0.817734</acceleration>
          <wrench>-44.8306 51.6008 1.95762 0 -0 0</wrench>
        </link>
        <link name='COL_COL_COL_VIS_VIS_VIS_VIS_VIS_VIS_VIS_VIS_VIS_hollie_real.005'>
          <pose frame=''>1.02014 1.97781 1.78473 -0.001387 -0.000628 2.23446</pose>
          <velocity>-0.057569 0.001115 -0.003924 0.10999 0.008234 -2.92532</velocity>
          <acceleration>-113.306 -1.03229 2.47523 -1.72226 0.872162 -1.29609</acceleration>
          <wrench>-92.7977 -0.845444 2.02721 0 -0 0</wrench>
        </link>
        <link name='COL_COL_COL_VIS_VIS_VIS_VIS_VIS_VIS_VIS_VIS_VIS_hollie_real.006'>
          <pose frame=''>1.02006 1.97768 1.88473 -0.001378 -0.000629 2.23446</pose>
          <velocity>-0.062102 -0.010255 -0.003863 0.102414 0.019174 -2.92532</velocity>
          <acceleration>-122.556 -24.5936 3.06164 -0.798597 -1.47972 1.85362</acceleration>
          <wrench>-0.001226 -0.000246 3.1e-05 0 -0 0</wrench>
        </link>
        <link name='COL_COL_COL_VIS_VIS_VIS_VIS_VIS_VIS_VIS_VIS_VIS_hollie_real.007'>
          <pose frame=''>1.03042 1.98576 1.88474 -0.001369 -0.00063 2.23446</pose>
          <velocity>-0.023038 -0.037021 -0.003554 0.094659 0.030372 -2.9253</velocity>
          <acceleration>-33.4968 -92.8583 2.81688 -0.286636 1.50945 -1.23565</acceleration>
          <wrench>-0.000335 -0.000929 2.8e-05 0 -0 0</wrench>
        </link>
        <link name='COL_COL_COL_VIS_VIS_VIS_VIS_VIS_VIS_VIS_VIS_VIS_hollie_real.008'>
          <pose frame=''>0.999 1.98296 1.88464 0.010073 0.26297 -2.43685</pose>
          <velocity>-0.024682 0.065908 -0.006996 -0.49689 -0.399398 -0.207925</velocity>
          <acceleration>-55.4311 161.388 -8.65939 0.036055 -0.35468 0.548986</acceleration>
          <wrench>-0.000554 0.001614 -8.7e-05 0 -0 0</wrench>
        </link>
        <link name='COL_COL_COL_VIS_VIS_VIS_VIS_VIS_VIS_VIS_VIS_VIS_hollie_real.009'>
          <pose frame=''>0.989602 1.97557 1.92901 -1.88272 -0.560414 2.44529</pose>
          <velocity>-0.044898 0.089228 0.002261 0.137367 0.144106 0.016906</velocity>
          <acceleration>-107.079 221.245 10.661 1.92111 1.42504 -1.97234</acceleration>
          <wrench>-0.001071 0.002212 0.000107 0 -0 0</wrench>
        </link>
        <link name='COL_COL_COL_VIS_VIS_VIS_VIS_VIS_VIS_VIS_VIS_VIS_hollie_real.010'>
          <pose frame=''>0.958088 2.00192 1.95478 -1.88262 -0.55991 2.4451</pose>
          <velocity>-0.040848 0.084964 0.008462 0.063927 0.0818 -0.009024</velocity>
          <acceleration>-106.678 216.442 12.1931 2.45639 0.074806 -1.40397</acceleration>
          <wrench>-0.001067 0.002164 0.000122 0 -0 0</wrench>
        </link>
        <link name='COL_COL_COL_VIS_VIS_VIS_VIS_VIS_VIS_VIS_VIS_VIS_hollie_real.011'>
          <pose frame=''>0.938591 2.01823 1.97071 -1.88258 -0.559715 2.44502</pose>
          <velocity>-0.039732 0.084056 0.010625 0.053053 0.071512 -0.013041</velocity>
          <acceleration>-108.728 215.586 11.7315 -1.25875 -0.430017 -2.87303</acceleration>
          <wrench>-0.001087 0.002156 0.000117 0 -0 0</wrench>
        </link>
        <link name='COL_COL_COL_VIS_VIS_VIS_VIS_VIS_VIS_VIS_VIS_VIS_hollie_real.012'>
          <pose frame=''>1.01496 2.00531 1.99473 -1.0456 -1.5681 -1.43233</pose>
          <velocity>0.071372 0.009581 -0.000903 -0.040258 -0.051702 -2.91816</velocity>
          <acceleration>181.818 22.3588 5.24231 -0.545514 0.331107 0.647814</acceleration>
          <wrench>0.001818 0.000224 5.2e-05 0 -0 0</wrench>
        </link>
        <link name='COL_COL_COL_VIS_VIS_VIS_VIS_VIS_VIS_VIS_VIS_VIS_hollie_real.013'>
          <pose frame=''>1.01496 2.00531 1.99473 -2.56185 -1.568 -1.48687</pose>
          <velocity>0.071856 0.009937 -0.001268 -0.057157 -0.030114 -2.91729</velocity>
          <acceleration>182.762 23.0876 4.36342 2.33103 1.04363 -0.738114</acceleration>
          <wrench>0.001828 0.000231 4.4e-05 0 -0 0</wrench>
        </link>
        <link name='COL_COL_COL_VIS_VIS_VIS_VIS_VIS_VIS_VIS_VIS_VIS_hollie_real.014'>
          <pose frame=''>1.01497 2.00517 2.04277 -2.51343 -1.56791 -1.53529</pose>
          <velocity>0.070057 0.01273 -0.001247 -0.05654 -0.030904 -2.91724</velocity>
          <acceleration>182.803 23.6498 4.41362 1.80551 -0.835393 2.49475</acceleration>
          <wrench>0.001828 0.000236 4.4e-05 0 -0 0</wrench>
        </link>
        <link name='COL_COL_COL_VIS_VIS_VIS_VIS_VIS_VIS_VIS_VIS_VIS_hollie_real.015'>
          <pose frame=''>1.01498 2.0051 2.06878 -2.48792 -1.56785 -1.5608</pose>
          <velocity>0.068638 0.014017 -0.001236 -0.056436 -0.031034 -2.91783</velocity>
          <acceleration>181.906 23.4609 4.45586 1.3412 -1.43517 1.31061</acceleration>
          <wrench>0.001819 0.000235 4.5e-05 0 -0 0</wrench>
        </link>
        <link name='COL_COL_COL_VIS_VIS_VIS_VIS_VIS_VIS_VIS_VIS_VIS_hollie_real.016'>
          <pose frame=''>1.03036 1.98561 1.99473 -0.439605 -1.5693 -2.03833</pose>
          <velocity>0.005386 -0.040167 -0.003913 0.087469 0.042334 -2.93389</velocity>
          <acceleration>21.6829 -99.7015 0.72941 1.39175 -0.121149 -2.7201</acceleration>
          <wrench>0.000217 -0.000997 7e-06 0 -0 0</wrench>
        </link>
        <link name='COL_COL_COL_VIS_VIS_VIS_VIS_VIS_VIS_VIS_VIS_VIS_hollie_real.017'>
          <pose frame=''>1.03036 1.98561 1.99473 -1.95489 -1.56909 -2.09384</pose>
          <velocity>0.005875 -0.040161 -0.003973 0.071043 0.063466 -2.93488</velocity>
          <acceleration>22.6281 -99.6828 0.570849 -2.59246 1.43363 1.58685</acceleration>
          <wrench>0.000226 -0.000997 6e-06 0 -0 0</wrench>
        </link>
        <link name='COL_COL_COL_VIS_VIS_VIS_VIS_VIS_VIS_VIS_VIS_VIS_hollie_real.018'>
          <pose frame=''>1.03031 1.98554 2.04477 -1.91433 -1.5689 -2.1344</pose>
          <velocity>0.008865 -0.043601 -0.003979 0.071155 0.063332 -2.93494</velocity>
          <acceleration>28.5071 -106.803 0.561372 2.96413 -1.51023 -1.68486</acceleration>
          <wrench>0.000285 -0.001068 6e-06 0 -0 0</wrench>
        </link>
        <link name='COL_COL_COL_VIS_VIS_VIS_VIS_VIS_VIS_VIS_VIS_VIS_hollie_real.019'>
          <pose frame=''>1.03028 1.98549 2.07677 -1.89505 -1.56879 -2.15368</pose>
          <velocity>0.010334 -0.045836 -0.003979 0.071038 0.063372 -2.9342</velocity>
          <acceleration>31.3115 -111.496 0.582356 -0.785096 -1.0899 2.94221</acceleration>
          <wrench>0.000313 -0.001115 6e-06 0 -0 0</wrench>
        </link>
        <link name='COL_COL_COL_VIS_VIS_VIS_VIS_VIS_VIS_VIS_VIS_VIS_hollie_real.020'>
          <pose frame=''>1.03767 1.96739 1.92222 -0.0014 -0.000546 2.29601</pose>
          <velocity>-0.045345 -0.063139 -0.005504 0.090044 0.032154 -0.905598</velocity>
          <acceleration>-69.0684 -161.645 -1.55427 -2.31231 0.603676 -2.86033</acceleration>
          <wrench>-0.000691 -0.001616 -1.6e-05 0 -0 0</wrench>
        </link>
        <link name='COL_COL_COL_VIS_VIS_VIS_VIS_VIS_VIS_VIS_VIS_VIS_hollie_real.021'>
          <pose frame=''>1.05896 1.95233 1.9782 3.04234 -1.5694 -2.31713</pose>
          <velocity>-0.022567 -0.076434 -0.006252 -0.027991 -0.050699 -0.905792</velocity>
          <acceleration>2.85879 -148.946 -6.14169 0.715169 1.01904 -3.09791</acceleration>
          <wrench>2.9e-05 -0.001489 -6.1e-05 0 -0 0</wrench>
        </link>
        <link name='COL_COL_COL_VIS_VIS_VIS_VIS_VIS_VIS_VIS_VIS_VIS_hollie_real.022'>
          <pose frame=''>1.05896 1.95233 1.9782 -1.65678 -1.56919 -2.33039</pose>
          <velocity>-0.021708 -0.076124 -0.005786 -0.043776 -0.03291 -0.905789</velocity>
          <acceleration>4.55809 -148.32 -5.14186 0.175869 0.345827 0.052136</acceleration>
          <wrench>4.6e-05 -0.001483 -5.1e-05 0 -0 0</wrench>
        </link>
        <link name='COL_COL_COL_VIS_VIS_VIS_VIS_VIS_VIS_VIS_VIS_VIS_hollie_real.023'>
          <pose frame=''>1.05892 1.95227 2.02273 -1.64726 -1.56899 -2.33991</pose>
          <velocity>-0.023124 -0.074096 -0.005781 -0.044045 -0.032606 -0.905789</velocity>
          <acceleration>4.88265 -148.121 -5.23139 -0.499473 0.024679 -3.09062</acceleration>
          <wrench>4.9e-05 -0.001481 -5.2e-05 0 -0 0</wrench>
        </link>
        <link name='COL_COL_COL_VIS_VIS_VIS_VIS_VIS_VIS_VIS_VIS_VIS_hollie_real.024'>
          <pose frame=''>1.05889 1.95224 2.04473 -1.64277 -1.56888 -2.3444</pose>
          <velocity>-0.02451 -0.073334 -0.005751 -0.044222 -0.032417 -0.905788</velocity>
          <acceleration>3.61405 -148.578 -5.1318 -1.05732 0.654798 -3.08817</acceleration>
          <wrench>3.6e-05 -0.001486 -5.1e-05 0 -0 0</wrench>
        </link>
        <link name='COL_COL_COL_VIS_VIS_VIS_VIS_VIS_VIS_VIS_VIS_VIS_hollie_real.025'>
          <pose frame=''>1.04469 1.9684 1.98772 3.04049 -1.5694 -2.31528</pose>
          <velocity>-0.017666 -0.068052 -0.004451 -0.02735 -0.052228 -0.905772</velocity>
          <acceleration>-16.9792 -158.758 -1.67084 2.78953 -1.28414 -3.05638</acceleration>
          <wrench>-0.00017 -0.001588 -1.7e-05 0 -0 0</wrench>
        </link>
        <link name='COL_COL_COL_VIS_VIS_VIS_VIS_VIS_VIS_VIS_VIS_VIS_hollie_real.026'>
          <pose frame=''>1.04469 1.9684 1.98771 -1.65818 -1.56919 -2.329</pose>
          <velocity>-0.014442 -0.067139 -0.004253 -0.044401 -0.032967 -0.905756</velocity>
          <acceleration>-10.6386 -156.914 -1.37535 0.055697 0.191724 0.119412</acceleration>
          <wrench>-0.000106 -0.001569 -1.4e-05 0 -0 0</wrench>
        </link>
        <link name='COL_COL_COL_VIS_VIS_VIS_VIS_VIS_VIS_VIS_VIS_VIS_hollie_real.027'>
          <pose frame=''>1.04464 1.96834 2.03775 -1.64832 -1.56898 -2.33886</pose>
          <velocity>-0.013492 -0.064109 -0.004292 -0.044649 -0.032638 -0.905744</velocity>
          <acceleration>-5.26072 -155.226 -1.62305 -0.491022 0.02205 -3.00162</acceleration>
          <wrench>-5.3e-05 -0.001552 -1.6e-05 0 -0 0</wrench>
        </link>
        <link name='COL_COL_COL_VIS_VIS_VIS_VIS_VIS_VIS_VIS_VIS_VIS_hollie_real_lef'>
          <pose frame=''>1.0446 1.9683 2.06975 -1.64365 -1.56887 -2.34353</pose>
          <velocity>-0.012545 -0.062059 -0.004322 -0.04483 -0.032395 -0.905734</velocity>
          <acceleration>-1.25764 -154.027 -1.77801 -1.071 0.664758 -2.98206</acceleration>
          <wrench>-1.3e-05 -0.00154 -1.8e-05 0 -0 0</wrench>
        </link>
        <link name='base_link'>
          <pose frame=''>1.00272 1.57632 0.019497 -0.00057 0.000577 3.10616</pose>
          <velocity>0.000494 7.3e-05 -0.005004 -0.003696 0.025299 1e-06</velocity>
          <acceleration>1.60805 -0.318369 0.975945 2.11191 -0.871774 -1.74091</acceleration>
          <wrench>1608.05 -318.369 975.945 0 -0 0</wrench>
        </link>
        <link name='hollie_real_left_arm_0_joint_link'>
          <pose frame=''>1.01628 1.97551 1.01973 0.000633 0.000508 -1.55385</pose>
          <velocity>0.016013 -0.001728 -0.005593 0.004 0.008328 0.005791</velocity>
          <acceleration>37.635 -3.23988 -2.37229 -3.06133 -0.382521 -2.75353</acceleration>
          <wrench>11.0511 -0.951359 -0.6966 0 -0 0</wrench>
        </link>
        <link name='hollie_real_left_hand_Thumb_Helper_link'>
          <pose frame=''>0.9896 1.97557 1.92901 -3.10419 -1.30764 -2.47558</pose>
          <velocity>-0.042802 0.089853 -0.007044 -0.498251 -0.397913 -0.207965</velocity>
          <acceleration>-102.55 222.551 -8.94767 0.45754 0.170515 -2.67601</acceleration>
          <wrench>-0.001025 0.002226 -8.9e-05 0 -0 0</wrench>
        </link>
        <link name='hollie_real_left_hand_f1_link'>
          <pose frame=''>1.03043 1.98576 1.88473 -0.001356 -0.000632 2.23446</pose>
          <velocity>0.004958 -0.028724 -0.004001 0.0847 0.046057 -2.92508</velocity>
          <acceleration>21.204 -75.8261 0.061086 2.25511 0.917856 2.33567</acceleration>
          <wrench>0.000212 -0.000758 1e-06 0 -0 0</wrench>
        </link>
        <link name='hollie_real_left_hand_f2_link'>
          <pose frame=''>1.03044 1.98576 1.88472 -0.001356 -0.000632 2.23446</pose>
          <velocity>0.006806 -0.027777 -0.004033 0.084192 0.046714 -2.92196</velocity>
          <acceleration>24.8159 -73.8685 -0.219041 -1.88276 0.931932 -0.848477</acceleration>
          <wrench>0.000248 -0.000739 -2e-06 0 -0 0</wrench>
        </link>
        <link name='hollie_real_left_hand_f3_link'>
          <pose frame=''>1.03044 1.98576 1.88472 -0.001356 -0.000632 2.23446</pose>
          <velocity>0.008267 -0.026993 -0.004049 0.084081 0.046739 -2.91955</velocity>
          <acceleration>27.6708 -72.2573 -0.415021 -2.1091 0.890201 -2.31489</acceleration>
          <wrench>0.000277 -0.000723 -4e-06 0 -0 0</wrench>
        </link>
        <link name='hollie_real_left_hand_f5_link'>
          <pose frame=''>1.04217 1.97137 1.92222 -0.001397 -0.000546 2.29601</pose>
          <velocity>-0.033583 -0.064876 -0.005455 0.086977 0.03639 -0.905596</velocity>
          <acceleration>-53.235 -156.755 -1.77043 1.03442 0.618316 0.285855</acceleration>
          <wrench>-0.000532 -0.001568 -1.8e-05 0 -0 0</wrench>
        </link>
        <link name='hollie_real_left_hand_f6_link'>
          <pose frame=''>1.04217 1.97137 1.92222 -0.001394 -0.000546 2.29601</pose>
          <velocity>-0.025567 -0.062488 -0.005593 0.084127 0.0403 -0.905593</velocity>
          <acceleration>-37.4735 -151.93 -2.42683 1.63966 -0.678336 0.291699</acceleration>
          <wrench>-0.000375 -0.001519 -2.4e-05 0 -0 0</wrench>
        </link>
        <link name='hollie_real_left_hand_f7_link'>
          <pose frame=''>1.04218 1.97137 1.92221 -0.001389 -0.000546 2.29601</pose>
          <velocity>-0.00946 -0.057302 -0.005949 0.079855 0.045961 -0.905589</velocity>
          <acceleration>-5.70124 -141.463 -3.94036 -0.718672 0.976369 0.297351</acceleration>
          <wrench>-5.7e-05 -0.001415 -3.9e-05 0 -0 0</wrench>
        </link>
        <link name='hollie_real_left_hand_f8_link'>
          <pose frame=''>1.04218 1.97137 1.92222 -0.001392 -0.000546 2.29601</pose>
          <velocity>-0.021498 -0.061413 -0.005632 0.082526 0.042517 -0.905583</velocity>
          <acceleration>-29.4944 -149.754 -2.68663 -1.54468 1.30123 0.310667</acceleration>
          <wrench>-0.000295 -0.001498 -2.7e-05 0 -0 0</wrench>
        </link>
      </model>
      <model name='ground_plane'>
        <pose frame=''>0 0 0 0 -0 0</pose>
        <link name='link'>
          <pose frame=''>0 0 0 0 -0 0</pose>
          <velocity>0 0 0 0 -0 0</velocity>
          <acceleration>0 0 0 0 -0 0</acceleration>
          <wrench>0 0 0 0 -0 0</wrench>
        </link>
      </model>
      <model name='unit_sphere_1'>
        <pose frame=''>1.01328 2.58099 1.01967 0 -0 0</pose>
        <link name='link'>
          <pose frame=''>1.01328 2.58099 1.01967 0 -0 0</pose>
          <velocity>0 0 0 0 -0 0</velocity>
          <acceleration>0 0 0 0 -0 0</acceleration>
          <wrench>0 0 0 0 -0 0</wrench>
        </link>
      </model>
    </state>
    <gui fullscreen='0'>
      <camera name='user_camera'>
        <pose frame=''>1.0188 2.77302 4.06029 0 1.4938 -1.535</pose>
        <view_controller>orbit</view_controller>
        <projection_type>perspective</projection_type>
      </camera>
    </gui>
    <model name='unit_sphere_1'>
      <static>1</static>
      <pose frame=''>1 -3 0.5 0 -0 0</pose>
      <link name='link'>
        <inertial>
          <mass>1</mass>
          <inertia>
            <ixx>0.1</ixx>
            <ixy>0</ixy>
            <ixz>0</ixz>
            <iyy>0.1</iyy>
            <iyz>0</iyz>
            <izz>0.1</izz>
          </inertia>
        </inertial>
        <collision name='collision'>
          <geometry>
            <sphere>
              <radius>0</radius>
            </sphere>
          </geometry>
          <max_contacts>10</max_contacts>
          <surface>
            <contact>
              <ode/>
            </contact>
            <bounce/>
            <friction>
              <ode/>
            </friction>
          </surface>
        </collision>
        <visual name='visual'>
          <geometry>
            <sphere>
              <radius>0.1</radius>
            </sphere>
          </geometry>
          <material>
            <script>
              <name>Gazebo/Grey</name>
              <uri>file://media/materials/scripts/gazebo.material</uri>
            </script>
          </material>
        </visual>
        <self_collide>0</self_collide>
        <kinematic>0</kinematic>
        <gravity>1</gravity>
      </link>
    </model>
  </world>
</sdf>
